Workbook

Sheet RESUMEN
A1: FULL — RESUMEN
A2: Se calcula solo desde la hoja FULL.
A4: ALERTA | B4: SKUs | C4: Unid. en Full | D4: Falta enviar | E4: Se puede enviar
A5: QUIEBRE Y SIN STOCK PARA ENVIAR | B5: =COUNTIF(FULL!$AL$7:$AL$128,$A5) -> 6 | C5: =SUMIF(FULL!$AL$7:$AL$128,$A5,FULL!$F$7:$F$128) -> 0 | D5: =SUMIF(FULL!$AL$7:$AL$128,$A5,FULL!$L$7:$L$128) -> 300 | E5: =SUMIF(FULL!$AL$7:$AL$128,$A5,FULL!$P$7:$P$128) -> 0
A6: QUIEBRE | B6: =COUNTIF(FULL!$AL$7:$AL$128,$A6) -> 39 | C6: =SUMIF(FULL!$AL$7:$AL$128,$A6,FULL!$F$7:$F$128) -> 0 | D6: =SUMIF(FULL!$AL$7:$AL$128,$A6,FULL!$L$7:$L$128) -> 1380 | E6: =SUMIF(FULL!$AL$7:$AL$128,$A6,FULL!$P$7:$P$128) -> 941
A7: REPONER | B7: =COUNTIF(FULL!$AL$7:$AL$128,$A7) -> 8 | C7: =SUMIF(FULL!$AL$7:$AL$128,$A7,FULL!$F$7:$F$128) -> 643 | D7: =SUMIF(FULL!$AL$7:$AL$128,$A7,FULL!$L$7:$L$128) -> 917 | E7: =SUMIF(FULL!$AL$7:$AL$128,$A7,FULL!$P$7:$P$128) -> 342
A8: EN RANGO | B8: =COUNTIF(FULL!$AL$7:$AL$128,$A8) -> 23 | C8: =SUMIF(FULL!$AL$7:$AL$128,$A8,FULL!$F$7:$F$128) -> 785 | D8: =SUMIF(FULL!$AL$7:$AL$128,$A8,FULL!$L$7:$L$128) -> 5 | E8: =SUMIF(FULL!$AL$7:$AL$128,$A8,FULL!$P$7:$P$128) -> 5
A9: SOBRE-STOCK | B9: =COUNTIF(FULL!$AL$7:$AL$128,$A9) -> 19 | C9: =SUMIF(FULL!$AL$7:$AL$128,$A9,FULL!$F$7:$F$128) -> 491 | D9: =SUMIF(FULL!$AL$7:$AL$128,$A9,FULL!$L$7:$L$128) -> 0 | E9: =SUMIF(FULL!$AL$7:$AL$128,$A9,FULL!$P$7:$P$128) -> 0
A10: SIN ROTACION | B10: =COUNTIF(FULL!$AL$7:$AL$128,$A10) -> 8 | C10: =SUMIF(FULL!$AL$7:$AL$128,$A10,FULL!$F$7:$F$128) -> 110 | D10: =SUMIF(FULL!$AL$7:$AL$128,$A10,FULL!$L$7:$L$128) -> 0 | E10: =SUMIF(FULL!$AL$7:$AL$128,$A10,FULL!$P$7:$P$128) -> 0
A11: STOCK VIEJO EN RIESGO | B11: =COUNTIF(FULL!$AL$7:$AL$128,$A11) -> 9 | C11: =SUMIF(FULL!$AL$7:$AL$128,$A11,FULL!$F$7:$F$128) -> 154 | D11: =SUMIF(FULL!$AL$7:$AL$128,$A11,FULL!$L$7:$L$128) -> 26 | E11: =SUMIF(FULL!$AL$7:$AL$128,$A11,FULL!$P$7:$P$128) -> 26
A12: SIN STOCK SIN DEMANDA | B12: =COUNTIF(FULL!$AL$7:$AL$128,$A12) -> 10 | C12: =SUMIF(FULL!$AL$7:$AL$128,$A12,FULL!$F$7:$F$128) -> 0 | D12: =SUMIF(FULL!$AL$7:$AL$128,$A12,FULL!$L$7:$L$128) -> 0 | E12: =SUMIF(FULL!$AL$7:$AL$128,$A12,FULL!$P$7:$P$128) -> 0
A13: - | B13: =COUNTIF(FULL!$AL$7:$AL$128,$A13) -> 0 | C13: =SUMIF(FULL!$AL$7:$AL$128,$A13,FULL!$F$7:$F$128) -> 0 | D13: =SUMIF(FULL!$AL$7:$AL$128,$A13,FULL!$L$7:$L$128) -> 0 | E13: =SUMIF(FULL!$AL$7:$AL$128,$A13,FULL!$P$7:$P$128) -> 0
A14: TOTAL | B14: =SUM(B5:B13) -> 122 | C14: =SUM(C5:C13) -> 2183 | D14: =SUM(D5:D13) -> 2628 | E14: =SUM(E5:E13) -> 1314
A16: CONFIABILIDAD DEL DATO
A17: SKUs con dato censurado | B17: =COUNTIF(FULL!$Z$7:$Z$128,"CENSURADO") -> 32 | C17: SKUs
A18: SKUs con dato confiable | B18: =COUNTIF(FULL!$Z$7:$Z$128,"CONFIABLE") -> 72 | C18: SKUs
A19: SKUs sin ventas en el período | B19: =COUNTIF(FULL!$Z$7:$Z$128,"SIN DATO") -> 18 | C19: SKUs
A20: Ventas diarias según reporte mensual | B20: =ROUND(SUMIF(FULL!$Z$7:$Z$128,"CENSURADO",FULL!$I$7:$I$128),1) -> 40.5 | C20: u/día
A21: Ventas diarias corregidas | B21: =ROUND(SUMIF(FULL!$Z$7:$Z$128,"CENSURADO",FULL!$J$7:$J$128),1) -> 76.1 | C21: u/día
A22: Cuánto subestima el reporte | B22: =IFERROR(ROUND(B21/B20,2),"") -> 1.88 | C22: veces
A24: ENVÍO
A25: Falta enviar (total) | B25: =SUM(FULL!$L$7:$L$128) -> 2628 | C25: u
A26: Se puede enviar con stock Táctica+ECOM | B26: =SUM(FULL!$P$7:$P$128) -> 1314 | C26: u
A27: No se puede cubrir por falta de stock propio | B27: =SUM(FULL!$L$7:$L$128)-SUM(FULL!$P$7:$P$128) -> 1314 | C27: u
A28: SKUs en cero en Full y sin stock para enviar | B28: =SUMPRODUCT((FULL!$F$7:$F$128=0)*(FULL!$L$7:$L$128>0)*(FULL!$O$7:$O$128=0)) -> 6 | C28: SKUs
A30: COSTO DEL MES
A31: Servicio de almacenamiento (30/06 al 29/07) | B31: 394485
A32: Cargo por stock antiguo | B32: =SUM(FULL!$AH$7:$AH$128) -> 482230
A33: Total | B33: =B31+B32 -> 876715
A35: LÍMITE DE LOS 180 DÍAS
A36: Unidades en franja 4-6 meses | B36: =SUM(FULL!$AF$7:$AF$128) -> 875 | C36: u
A37: Aumento total si todas cruzaran | B37: =SUM(FULL!$AI$7:$AI$128) -> 3513125
A38: Solo las marcadas STOCK VIEJO EN RIESGO — unidades | B38: =SUMIF(FULL!$AL$7:$AL$128,"STOCK VIEJO EN RIESGO",FULL!$AF$7:$AF$128) -> 81 | C38: u
A39: Solo las marcadas STOCK VIEJO EN RIESGO — aumento | B39: =SUMIF(FULL!$AL$7:$AL$128,"STOCK VIEJO EN RIESGO",FULL!$AI$7:$AI$128) -> 325215
A41: VALOR
A42: Unidades en Full | B42: =SUM(FULL!$F$7:$F$128) -> 2183 | C42: u
A43: Valor del stock en Full | B43: =SUM(FULL!$AK$7:$AK$128) -> 14766
A44: SKUs sin costo cargado | B44: =COUNTIF(FULL!$AJ$7:$AJ$128,0) -> 19 | C44: SKUs

Sheet FULL
A1: FULL — TABLA OPERATIVA
A2: Cuenta IT (115764017) · Ventas: 32 días al 11/08/2026 · Stock Full y cargos al 11/08/2026 · Stock Táctica/ECOM al 03/08/2026
A3: Semanas objetivo | C3: 3 | D3: Días del período de ventas | G3: 32 | H3: Fecha de corte | J3: 46245 | K3: Cargo unidad 4-6 meses | N3: 470 | O3: Cargo unidad +6 meses | Q3: 4485
A5: PARA ARMAR EL ENVÍO | Q5: CONTROL DE LA PUBLICACIÓN | T5: CÓMO SE MIDIÓ LA DEMANDA | AB5: CUÁNDO SE QUIEBRA | AD5: ANTIGÜEDAD Y CARGOS | AJ5: VALOR | AL5: ESTADO
A6: Cuenta | B6: Código ML | C6: SKU | D6: MLA (publicación) | E6: Título | F6: Stock en Full | G6: Envíos pendientes | H6: Ventas 30 días | I6: Ventas diarias simple | J6: Ventas diarias corregida | K6: Stock objetivo (semanas) | L6: Falta enviar | M6: Stock Táctica | N6: Stock ECOM | O6: Disponible T+E | P6: ENVIAR POSIBLE | Q6: Estado publicación | R6: Publ. | S6: Tamaño | T6: Unidades 32d | U6: Días con venta | V6: Ventana con stock | W6: Días sin vender | X6: Stock prom 30d ML | Y6: Rotación | Z6: Estado del dato | AA6: Factor | AB6: Cobertura (días) | AC6: Quiebre estimado | AD6: No aptas | AE6: Antigüedad máx | AF6: Unid. 4-6 meses | AG6: Días al límite 180 | AH6: Cargo actual | AI6: Aumento si cruza | AJ6: Costo USD | AK6: Valor en Full USD | AL6: ALERTA
A7: IT | B7: TNSC93322 | C7: CB435A-436A-CE285AUNIVCOMP | D7: 616880448 | E7: Toner Alternativo Para Cb436a 435a 36a P1505 M1120 M1522 Negro | F7: 566 | G7: 0 | H7: 1835 | I7: =ROUND($H7/30,2) -> 61.17 | J7: =IF($Z7="CENSURADO",ROUND($T7/MAX($V7,3),2),ROUND($T7/$G$3,2)) -> 61.47 | K7: =ROUNDUP($J7*$C$3*7,0) -> 1291 | L7: =MAX(0,$K7-$F7-$G7) -> 725 | M7: 160 | N7: -1 | O7: =$M7+$N7 -> 159 | P7: =MIN($L7,$O7) -> 159 | Q7: Activa | R7: 12 | S7: Mediano | T7: 1967 | U7: 32 | V7: 32 | W7: 0 | X7: 1560 | Y7: =IF($X7=0,"",ROUND($H7/$X7,2)) -> 1.18 | Z7: =IF(AND($F7=0,$T7>=5,$W7>=3),"CENSURADO",IF(AND($Y7<>"",$Y7>=3,$T7>=10),"CENSURADO",IF($T7=0,"SIN DATO","CONFIABLE"))) -> CONFIABLE | AA7: =IF($I7=0,"",ROUND($J7/MAX($I7,0.01),2)) -> 1 | AB7: =IF($J7<=0,"",ROUND(($F7+$G7)/$J7,0)) -> 9 | AC7: =IF($AB7="","",$J$3+$AB7) -> 46254 | AD7: 0 | AE7: 170 | AF7: 681 | AG7: =IF($AF7=0,"",MAX(0,180-$AE7)) -> 10 | AH7: 320070 | AI7: =IF($AF7=0,"",$AF7*$Q$3-$AF7*$N$3) -> 2734215 | AJ7: 2.81 | AK7: =ROUND($F7*$AJ7,0) -> 1590 | AL7: =IF(AND($F7=0,$T7>0,$O7=0),"QUIEBRE Y SIN STOCK PARA ENVIAR",IF(AND($F7=0,$T7>0),"QUIEBRE",IF($F7=0,"SIN STOCK SIN DEMANDA",IF(AND($AF7>0,$AG7<>"",OR($AB7="",$AB7>$AG7)),"STOCK VIEJO EN RIESGO",IF(AND($T7=0,$H7=0),"SIN ROTACION",IF($AB7="","-",IF($AB7<14,"REPONER",IF($AB7>84,"SOBRE-STOCK","EN RANGO")))))))) -> REPONER
A8: IT | B8: WRRA16826 | C8: MLTD111SCOMPV2 | D8: 1431106425 | 630220607 | E8: Toner Alternativo Para Samsung D111 M2020w 2020 M2070w 2070w Negro | F8: 0 | G8: 0 | H8: 396 | I8: =ROUND($H8/30,2) -> 13.2 | J8: =IF($Z8="CENSURADO",ROUND($T8/MAX($V8,3),2),ROUND($T8/$G$3,2)) -> 15.88 | K8: =ROUNDUP($J8*$C$3*7,0) -> 334 | L8: =MAX(0,$K8-$F8-$G8) -> 334 | M8: 30 | N8: -5 | O8: =$M8+$N8 -> 25 | P8: =MIN($L8,$O8) -> 25 | R8: 2 | S8: Mediano | T8: 397 | U8: 25 | V8: 25 | W8: 7 | X8: 155 | Y8: =IF($X8=0,"",ROUND($H8/$X8,2)) -> 2.55 | Z8: =IF(AND($F8=0,$T8>=5,$W8>=3),"CENSURADO",IF(AND($Y8<>"",$Y8>=3,$T8>=10),"CENSURADO",IF($T8=0,"SIN DATO","CONFIABLE"))) -> CENSURADO | AA8: =IF($I8=0,"",ROUND($J8/MAX($I8,0.01),2)) -> 1.2 | AB8: =IF($J8<=0,"",ROUND(($F8+$G8)/$J8,0)) -> 0 | AC8: =IF($AB8="","",$J$3+$AB8) -> 46245 | AD8: 0 | AE8: 0 | AF8: 0 | AG8: =IF($AF8=0,"",MAX(0,180-$AE8)) | AH8: 0 | AI8: =IF($AF8=0,"",$AF8*$Q$3-$AF8*$N$3) | AJ8: 2.64 | AK8: =ROUND($F8*$AJ8,0) -> 0 | AL8: =IF(AND($F8=0,$T8>0,$O8=0),"QUIEBRE Y SIN STOCK PARA ENVIAR",IF(AND($F8=0,$T8>0),"QUIEBRE",IF($F8=0,"SIN STOCK SIN DEMANDA",IF(AND($AF8>0,$AG8<>"",OR($AB8="",$AB8>$AG8)),"STOCK VIEJO EN RIESGO",IF(AND($T8=0,$H8=0),"SIN ROTACION",IF($AB8="","-",IF($AB8<14,"REPONER",IF($AB8>84,"SOBRE-STOCK","EN RANGO")))))))) -> QUIEBRE
A9: IT | B9: DUHF44843 | C9: CF217ACOMP | D9: 751602895 | E9: Toner Alternativo Para Cf217a M102 M130 217a 17a Con Chip Negro/tricolor Impreso | F9: 67 | G9: 210 | H9: 204 | I9: =ROUND($H9/30,2) -> 6.8 | J9: =IF($Z9="CENSURADO",ROUND($T9/MAX($V9,3),2),ROUND($T9/$G$3,2)) -> 9.69 | K9: =ROUNDUP($J9*$C$3*7,0) -> 204 | L9: =MAX(0,$K9-$F9-$G9) -> 0 | M9: 5687 | N9: 1169 | O9: =$M9+$N9 -> 6856 | P9: =MIN($L9,$O9) -> 0 | Q9: Activa | R9: 2 | S9: Mediano | T9: 310 | U9: 26 | V9: 30 | W9: 1 | X9: 153 | Y9: =IF($X9=0,"",ROUND($H9/$X9,2)) -> 1.33 | Z9: =IF(AND($F9=0,$T9>=5,$W9>=3),"CENSURADO",IF(AND($Y9<>"",$Y9>=3,$T9>=10),"CENSURADO",IF($T9=0,"SIN DATO","CONFIABLE"))) -> CONFIABLE | AA9: =IF($I9=0,"",ROUND($J9/MAX($I9,0.01),2)) -> 1.43 | AB9: =IF($J9<=0,"",ROUND(($F9+$G9)/$J9,0)) -> 29 | AC9: =IF($AB9="","",$J$3+$AB9) -> 46274 | AD9: 0 | AE9: 0 | AF9: 0 | AG9: =IF($AF9=0,"",MAX(0,180-$AE9)) | AH9: 0 | AI9: =IF($AF9=0,"",$AF9*$Q$3-$AF9*$N$3) | AJ9: 2.65 | AK9: =ROUND($F9*$AJ9,0) -> 178 | AL9: =IF(AND($F9=0,$T9>0,$O9=0),"QUIEBRE Y SIN STOCK PARA ENVIAR",IF(AND($F9=0,$T9>0),"QUIEBRE",IF($F9=0,"SIN STOCK SIN DEMANDA",IF(AND($AF9>0,$AG9<>"",OR($AB9="",$AB9>$AG9)),"STOCK VIEJO EN RIESGO",IF(AND($T9=0,$H9=0),"SIN ROTACION",IF($AB9="","-",IF($AB9<14,"REPONER",IF($AB9>84,"SOBRE-STOCK","EN RANGO")))))))) -> EN RANGO
A10: IT | B10: OJMY16755 | C10: CF279ACOMP | D10: 762970302 | E10: Toner Alternativo M12w M12 12w M26nw M12a M26 Cf279 79a 279a Negro | F10: 0 | G10: 0 | H10: 0 | I10: =ROUND($H10/30,2) -> 0 | J10: =IF($Z10="CENSURADO",ROUND($T10/MAX($V10,3),2),ROUND($T10/$G$3,2)) -> 9.16 | K10: =ROUNDUP($J10*$C$3*7,0) -> 193 | L10: =MAX(0,$K10-$F10-$G10) -> 193 | M10: 519 | N10: 1392 | O10: =$M10+$N10 -> 1911 | P10: =MIN($L10,$O10) -> 193 | Q10: Activa | R10: 1 | S10: Mediano | T10: 293 | U10: 28 | V10: 31 | W10: 1 | X10: 0 | Y10: =IF($X10=0,"",ROUND($H10/$X10,2)) | Z10: =IF(AND($F10=0,$T10>=5,$W10>=3),"CENSURADO",IF(AND($Y10<>"",$Y10>=3,$T10>=10),"CENSURADO",IF($T10=0,"SIN DATO","CONFIABLE"))) -> CONFIABLE | AA10: =IF($I10=0,"",ROUND($J10/MAX($I10,0.01),2)) | AB10: =IF($J10<=0,"",ROUND(($F10+$G10)/$J10,0)) -> 0 | AC10: =IF($AB10="","",$J$3+$AB10) -> 46245 | AD10: 0 | AE10: 0 | AF10: 0 | AG10: =IF($AF10=0,"",MAX(0,180-$AE10)) | AH10: 0 | AI10: =IF($AF10=0,"",$AF10*$Q$3-$AF10*$N$3) | AJ10: 2.15 | AK10: =ROUND($F10*$AJ10,0) -> 0 | AL10: =IF(AND($F10=0,$T10>0,$O10=0),"QUIEBRE Y SIN STOCK PARA ENVIAR",IF(AND($F10=0,$T10>0),"QUIEBRE",IF($F10=0,"SIN STOCK SIN DEMANDA",IF(AND($AF10>0,$AG10<>"",OR($AB10="",$AB10>$AG10)),"STOCK VIEJO EN RIESGO",IF(AND($T10=0,$H10=0),"SIN ROTACION",IF($AB10="","-",IF($AB10<14,"REPONER",IF($AB10>84,"SOBRE-STOCK","EN RANGO")))))))) -> QUIEBRE
A11: IT | B11: XACN86724 | C11: Q2612ACOMP | D11: 1457999139 | E11: Tóner Compatible Con Hp 2612a Para 1010 1012 1015 1018 - Rendimiendo De 2000 Pág | F11: 380 | G11: 150 | H11: 188 | I11: =ROUND($H11/30,2) -> 6.27 | J11: =IF($Z11="CENSURADO",ROUND($T11/MAX($V11,3),2),ROUND($T11/$G$3,2)) -> 8.56 | K11: =ROUNDUP($J11*$C$3*7,0) -> 180 | L11: =MAX(0,$K11-$F11-$G11) -> 0 | M11: 6241 | N11: 438 | O11: =$M11+$N11 -> 6679 | P11: =MIN($L11,$O11) -> 0 | Q11: Activa | R11: 4 | S11: Mediano | T11: 274 | U11: 27 | V11: 32 | W11: 0 | X11: 445 | Y11: =IF($X11=0,"",ROUND($H11/$X11,2)) -> 0.42 | Z11: =IF(AND($F11=0,$T11>=5,$W11>=3),"CENSURADO",IF(AND($Y11<>"",$Y11>=3,$T11>=10),"CENSURADO",IF($T11=0,"SIN DATO","CONFIABLE"))) -> CONFIABLE | AA11: =IF($I11=0,"",ROUND($J11/MAX($I11,0.01),2)) -> 1.37 | AB11: =IF($J11<=0,"",ROUND(($F11+$G11)/$J11,0)) -> 62 | AC11: =IF($AB11="","",$J$3+$AB11) -> 46307 | AD11: 0 | AE11: 0 | AF11: 0 | AG11: =IF($AF11=0,"",MAX(0,180-$AE11)) | AH11: 0 | AI11: =IF($AF11=0,"",$AF11*$Q$3-$AF11*$N$3) | AJ11: 2.84 | AK11: =ROUND($F11*$AJ11,0) -> 1079 | AL11: =IF(AND($F11=0,$T11>0,$O11=0),"QUIEBRE Y SIN STOCK PARA ENVIAR",IF(AND($F11=0,$T11>0),"QUIEBRE",IF($F11=0,"SIN STOCK SIN DEMANDA",IF(AND($AF11>0,$AG11<>"",OR($AB11="",$AB11>$AG11)),"STOCK VIEJO EN RIESGO",IF(AND($T11=0,$H11=0),"SIN ROTACION",IF($AB11="","-",IF($AB11<14,"REPONER",IF($AB11>84,"SOBRE-STOCK","EN RANGO")))))))) -> EN RANGO
A12: IT | B12: LRKS64658 | C12: LAM-ROLL-M-330MM-150MTS-32MIC | D12: 810844083 | E12: Rollo Para Laminar Mate 32 Micrones 330 Mm 150 Metros | F12: 0 | G12: 100 | H12: 123 | I12: =ROUND($H12/30,2) -> 4.1 | J12: =IF($Z12="CENSURADO",ROUND($T12/MAX($V12,3),2),ROUND($T12/$G$3,2)) -> 7.89 | K12: =ROUNDUP($J12*$C$3*7,0) -> 166 | L12: =MAX(0,$K12-$F12-$G12) -> 66 | M12: 174 | N12: 16 | O12: =$M12+$N12 -> 190 | P12: =MIN($L12,$O12) -> 66 | R12: 1 | S12: Mediano | T12: 213 | U12: 26 | V12: 27 | W12: 4 | X12: 45 | Y12: =IF($X12=0,"",ROUND($H12/$X12,2)) -> 2.73 | Z12: =IF(AND($F12=0,$T12>=5,$W12>=3),"CENSURADO",IF(AND($Y12<>"",$Y12>=3,$T12>=10),"CENSURADO",IF($T12=0,"SIN DATO","CONFIABLE"))) -> CENSURADO | AA12: =IF($I12=0,"",ROUND($J12/MAX($I12,0.01),2)) -> 1.92 | AB12: =IF($J12<=0,"",ROUND(($F12+$G12)/$J12,0)) -> 13 | AC12: =IF($AB12="","",$J$3+$AB12) -> 46258 | AD12: 0 | AE12: 0 | AF12: 0 | AG12: =IF($AF12=0,"",MAX(0,180-$AE12)) | AH12: 0 | AI12: =IF($AF12=0,"",$AF12*$Q$3-$AF12*$N$3) | AJ12: 5.74 | AK12: =ROUND($F12*$AJ12,0) -> 0 | AL12: =IF(AND($F12=0,$T12>0,$O12=0),"QUIEBRE Y SIN STOCK PARA ENVIAR",IF(AND($F12=0,$T12>0),"QUIEBRE",IF($F12=0,"SIN STOCK SIN DEMANDA",IF(AND($AF12>0,$AG12<>"",OR($AB12="",$AB12>$AG12)),"STOCK VIEJO EN RIESGO",IF(AND($T12=0,$H12=0),"SIN ROTACION",IF($AB12="","-",IF($AB12<14,"REPONER",IF($AB12>84,"SOBRE-STOCK","EN RANGO")))))))) -> QUIEBRE
A13: IT | B13: GKVM85194 | C13: MLTD101SCOMP | D13: 929612123 | E13: Toner Alternativo Para 101 Mlt D101l Ml 2165w 1500k Negro | F13: 57 | G13: 85 | H13: 105 | I13: =ROUND($H13/30,2) -> 3.5 | J13: =IF($Z13="CENSURADO",ROUND($T13/MAX($V13,3),2),ROUND($T13/$G$3,2)) -> 6 | K13: =ROUNDUP($J13*$C$3*7,0) -> 126 | L13: =MAX(0,$K13-$F13-$G13) -> 0 | M13: 9733 | N13: 202 | O13: =$M13+$N13 -> 9935 | P13: =MIN($L13,$O13) -> 0 | Q13: Activa | R13: 3 | S13: Mediano | T13: 192 | U13: 28 | V13: 32 | W13: 0 | X13: 99 | Y13: =IF($X13=0,"",ROUND($H13/$X13,2)) -> 1.06 | Z13: =IF(AND($F13=0,$T13>=5,$W13>=3),"CENSURADO",IF(AND($Y13<>"",$Y13>=3,$T13>=10),"CENSURADO",IF($T13=0,"SIN DATO","CONFIABLE"))) -> CONFIABLE | AA13: =IF($I13=0,"",ROUND($J13/MAX($I13,0.01),2)) -> 1.71 | AB13: =IF($J13<=0,"",ROUND(($F13+$G13)/$J13,0)) -> 24 | AC13: =IF($AB13="","",$J$3+$AB13) -> 46269 | AD13: 0 | AE13: 0 | AF13: 0 | AG13: =IF($AF13=0,"",MAX(0,180-$AE13)) | AH13: 0 | AI13: =IF($AF13=0,"",$AF13*$Q$3-$AF13*$N$3) | AJ13: 4.1 | AK13: =ROUND($F13*$AJ13,0) -> 234 | AL13: =IF(AND($F13=0,$T13>0,$O13=0),"QUIEBRE Y SIN STOCK PARA ENVIAR",IF(AND($F13=0,$T13>0),"QUIEBRE",IF($F13=0,"SIN STOCK SIN DEMANDA",IF(AND($AF13>0,$AG13<>"",OR($AB13="",$AB13>$AG13)),"STOCK VIEJO EN RIESGO",IF(AND($T13=0,$H13=0),"SIN ROTACION",IF($AB13="","-",IF($AB13<14,"REPONER",IF($AB13>84,"SOBRE-STOCK","EN RANGO")))))))) -> EN RANGO
A14: IT | B14: TGMU01761 | C14: CIZALLA-A4-12EN1 | D14: 1475792185 | 2384987536 | E14: Guillotina Rotativa Cizalla Corta Papel A4 300mm 12 En 1 | F14: 10 | G14: 50 | H14: 96 | I14: =ROUND($H14/30,2) -> 3.2 | J14: =IF($Z14="CENSURADO",ROUND($T14/MAX($V14,3),2),ROUND($T14/$G$3,2)) -> 4.78 | K14: =ROUNDUP($J14*$C$3*7,0) -> 101 | L14: =MAX(0,$K14-$F14-$G14) -> 41 | M14: 1217 | N14: 32 | O14: =$M14+$N14 -> 1249 | P14: =MIN($L14,$O14) -> 41 | Q14: Activa | R14: 1 | S14: Mediano | T14: 153 | U14: 30 | V14: 30 | W14: 0 | X14: 65 | Y14: =IF($X14=0,"",ROUND($H14/$X14,2)) -> 1.48 | Z14: =IF(AND($F14=0,$T14>=5,$W14>=3),"CENSURADO",IF(AND($Y14<>"",$Y14>=3,$T14>=10),"CENSURADO",IF($T14=0,"SIN DATO","CONFIABLE"))) -> CONFIABLE | AA14: =IF($I14=0,"",ROUND($J14/MAX($I14,0.01),2)) -> 1.49 | AB14: =IF($J14<=0,"",ROUND(($F14+$G14)/$J14,0)) -> 13 | AC14: =IF($AB14="","",$J$3+$AB14) -> 46258 | AD14: 0 | AE14: 0 | AF14: 0 | AG14: =IF($AF14=0,"",MAX(0,180-$AE14)) | AH14: 0 | AI14: =IF($AF14=0,"",$AF14*$Q$3-$AF14*$N$3) | AJ14: 6.1 | AK14: =ROUND($F14*$AJ14,0) -> 61 | AL14: =IF(AND($F14=0,$T14>0,$O14=0),"QUIEBRE Y SIN STOCK PARA ENVIAR",IF(AND($F14=0,$T14>0),"QUIEBRE",IF($F14=0,"SIN STOCK SIN DEMANDA",IF(AND($AF14>0,$AG14<>"",OR($AB14="",$AB14>$AG14)),"STOCK VIEJO EN RIESGO",IF(AND($T14=0,$H14=0),"SIN ROTACION",IF($AB14="","-",IF($AB14<14,"REPONER",IF($AB14>84,"SOBRE-STOCK","EN RANGO")))))))) -> REPONER
A15: IT | B15: VTUA74073 | C15: PLANCHA-SUB-PORTATIL | D15: 2091207644 | 3655836976 | E15: Estampadora Textil Portátil 10.5 Cm Blanco | F15: 56 | G15: 50 | H15: 9 | I15: =ROUND($H15/30,2) -> 0.3 | J15: =IF($Z15="CENSURADO",ROUND($T15/MAX($V15,3),2),ROUND($T15/$G$3,2)) -> 4.38 | K15: =ROUNDUP($J15*$C$3*7,0) -> 92 | L15: =MAX(0,$K15-$F15-$G15) -> 0 | M15: 167 | N15: 408 | O15: =$M15+$N15 -> 575 | P15: =MIN($L15,$O15) -> 0 | Q15: Activa | R15: 2 | S15: Pequeño | T15: 140 | U15: 24 | V15: 31 | W15: 0 | X15: 59 | Y15: =IF($X15=0,"",ROUND($H15/$X15,2)) -> 0.15 | Z15: =IF(AND($F15=0,$T15>=5,$W15>=3),"CENSURADO",IF(AND($Y15<>"",$Y15>=3,$T15>=10),"CENSURADO",IF($T15=0,"SIN DATO","CONFIABLE"))) -> CONFIABLE | AA15: =IF($I15=0,"",ROUND($J15/MAX($I15,0.01),2)) -> 14.6 | AB15: =IF($J15<=0,"",ROUND(($F15+$G15)/$J15,0)) -> 24 | AC15: =IF($AB15="","",$J$3+$AB15) -> 46269 | AD15: 0 | AE15: 0 | AF15: 0 | AG15: =IF($AF15=0,"",MAX(0,180-$AE15)) | AH15: 0 | AI15: =IF($AF15=0,"",$AF15*$Q$3-$AF15*$N$3) | AJ15: 13.25 | AK15: =ROUND($F15*$AJ15,0) -> 742 | AL15: =IF(AND($F15=0,$T15>0,$O15=0),"QUIEBRE Y SIN STOCK PARA ENVIAR",IF(AND($F15=0,$T15>0),"QUIEBRE",IF($F15=0,"SIN STOCK SIN DEMANDA",IF(AND($AF15>0,$AG15<>"",OR($AB15="",$AB15>$AG15)),"STOCK VIEJO EN RIESGO",IF(AND($T15=0,$H15=0),"SIN ROTACION",IF($AB15="","-",IF($AB15<14,"REPONER",IF($AB15>84,"SOBRE-STOCK","EN RANGO")))))))) -> EN RANGO
A16: IT | B16: GZFD15414 | C16: X2 CB435A-436A-CE285AUNIVCOMP | D16: 2693713220 | 606715836 | E16: Toner Alternativo Para 285a 435a 436a 1102w 1102 Pack X 2 Negro | F16: 0 | G16: 0 | H16: 119 | I16: =ROUND($H16/30,2) -> 3.97 | J16: =IF($Z16="CENSURADO",ROUND($T16/MAX($V16,3),2),ROUND($T16/$G$3,2)) -> 4.17 | K16: =ROUNDUP($J16*$C$3*7,0) -> 88 | L16: =MAX(0,$K16-$F16-$G16) -> 88 | M16: 0 | N16: 0 | O16: =$M16+$N16 -> 0 | P16: =MIN($L16,$O16) -> 0 | R16: 1 | S16: Mediano | T16: 121 | U16: 22 | V16: 29 | W16: 3 | X16: 70 | Y16: =IF($X16=0,"",ROUND($H16/$X16,2)) -> 1.7 | Z16: =IF(AND($F16=0,$T16>=5,$W16>=3),"CENSURADO",IF(AND($Y16<>"",$Y16>=3,$T16>=10),"CENSURADO",IF($T16=0,"SIN DATO","CONFIABLE"))) -> CENSURADO | AA16: =IF($I16=0,"",ROUND($J16/MAX($I16,0.01),2)) -> 1.05 | AB16: =IF($J16<=0,"",ROUND(($F16+$G16)/$J16,0)) -> 0 | AC16: =IF($AB16="","",$J$3+$AB16) -> 46245 | AD16: 0 | AE16: 0 | AF16: 0 | AG16: =IF($AF16=0,"",MAX(0,180-$AE16)) | AH16: 0 | AI16: =IF($AF16=0,"",$AF16*$Q$3-$AF16*$N$3) | AJ16: 0 | AK16: =ROUND($F16*$AJ16,0) -> 0 | AL16: =IF(AND($F16=0,$T16>0,$O16=0),"QUIEBRE Y SIN STOCK PARA ENVIAR",IF(AND($F16=0,$T16>0),"QUIEBRE",IF($F16=0,"SIN STOCK SIN DEMANDA",IF(AND($AF16>0,$AG16<>"",OR($AB16="",$AB16>$AG16)),"STOCK VIEJO EN RIESGO",IF(AND($T16=0,$H16=0),"SIN ROTACION",IF($AB16="","-",IF($AB16<14,"REPONER",IF($AB16>84,"SOBRE-STOCK","EN RANGO")))))))) -> QUIEBRE Y SIN STOCK PARA ENVIAR
A17: IT | B17: ESMW22207 | C17: EMERLIGHT-30LED | D17: 1607486745 | E17: Luces Luz De Emergencia 30 Leds Bateria Recargable Seguridad - Marca Global Elec | F17: 37 | G17: 0 | H17: 67 | I17: =ROUND($H17/30,2) -> 2.23 | J17: =IF($Z17="CENSURADO",ROUND($T17/MAX($V17,3),2),ROUND($T17/$G$3,2)) -> 3.69 | K17: =ROUNDUP($J17*$C$3*7,0) -> 78 | L17: =MAX(0,$K17-$F17-$G17) -> 41 | M17: 271 | N17: 88 | O17: =$M17+$N17 -> 359 | P17: =MIN($L17,$O17) -> 41 | Q17: Activa | R17: 1 | S17: Pequeño | T17: 118 | U17: 22 | V17: 30 | W17: 1 | X17: 83 | Y17: =IF($X17=0,"",ROUND($H17/$X17,2)) -> 0.81 | Z17: =IF(AND($F17=0,$T17>=5,$W17>=3),"CENSURADO",IF(AND($Y17<>"",$Y17>=3,$T17>=10),"CENSURADO",IF($T17=0,"SIN DATO","CONFIABLE"))) -> CONFIABLE | AA17: =IF($I17=0,"",ROUND($J17/MAX($I17,0.01),2)) -> 1.65 | AB17: =IF($J17<=0,"",ROUND(($F17+$G17)/$J17,0)) -> 10 | AC17: =IF($AB17="","",$J$3+$AB17) -> 46255 | AD17: 0 | AE17: 0 | AF17: 0 | AG17: =IF($AF17=0,"",MAX(0,180-$AE17)) | AH17: 0 | AI17: =IF($AF17=0,"",$AF17*$Q$3-$AF17*$N$3) | AJ17: 1.55 | AK17: =ROUND($F17*$AJ17,0) -> 57 | AL17: =IF(AND($F17=0,$T17>0,$O17=0),"QUIEBRE Y SIN STOCK PARA ENVIAR",IF(AND($F17=0,$T17>0),"QUIEBRE",IF($F17=0,"SIN STOCK SIN DEMANDA",IF(AND($AF17>0,$AG17<>"",OR($AB17="",$AB17>$AG17)),"STOCK VIEJO EN RIESGO",IF(AND($T17=0,$H17=0),"SIN ROTACION",IF($AB17="","-",IF($AB17<14,"REPONER",IF($AB17>84,"SOBRE-STOCK","EN RANGO")))))))) -> REPONER
A18: IT | B18: YAEM28869 | C18: CUTTERCIRCLE | D18: 2000771898 | E18: Cutter Compas Cortante Circular De 100 A 320 Mm | F18: 0 | G18: 50 | H18: 58 | I18: =ROUND($H18/30,2) -> 1.93 | J18: =IF($Z18="CENSURADO",ROUND($T18/MAX($V18,3),2),ROUND($T18/$G$3,2)) -> 3.34 | K18: =ROUNDUP($J18*$C$3*7,0) -> 71 | L18: =MAX(0,$K18-$F18-$G18) -> 21 | M18: 3338 | N18: 31 | O18: =$M18+$N18 -> 3369 | P18: =MIN($L18,$O18) -> 21 | Q18: Activa | R18: 1 | S18: Mediano | T18: 107 | U18: 30 | V18: 32 | W18: 0 | X18: 16 | Y18: =IF($X18=0,"",ROUND($H18/$X18,2)) -> 3.63 | Z18: =IF(AND($F18=0,$T18>=5,$W18>=3),"CENSURADO",IF(AND($Y18<>"",$Y18>=3,$T18>=10),"CENSURADO",IF($T18=0,"SIN DATO","CONFIABLE"))) -> CENSURADO | AA18: =IF($I18=0,"",ROUND($J18/MAX($I18,0.01),2)) -> 1.73 | AB18: =IF($J18<=0,"",ROUND(($F18+$G18)/$J18,0)) -> 15 | AC18: =IF($AB18="","",$J$3+$AB18) -> 46260 | AD18: 0 | AE18: 0 | AF18: 0 | AG18: =IF($AF18=0,"",MAX(0,180-$AE18)) | AH18: 0 | AI18: =IF($AF18=0,"",$AF18*$Q$3-$AF18*$N$3) | AJ18: 2.48 | AK18: =ROUND($F18*$AJ18,0) -> 0 | AL18: =IF(AND($F18=0,$T18>0,$O18=0),"QUIEBRE Y SIN STOCK PARA ENVIAR",IF(AND($F18=0,$T18>0),"QUIEBRE",IF($F18=0,"SIN STOCK SIN DEMANDA",IF(AND($AF18>0,$AG18<>"",OR($AB18="",$AB18>$AG18)),"STOCK VIEJO EN RIESGO",IF(AND($T18=0,$H18=0),"SIN ROTACION",IF($AB18="","-",IF($AB18<14,"REPONER",IF($AB18>84,"SOBRE-STOCK","EN RANGO")))))))) -> QUIEBRE
A19: IT | B19: HLNI07986 | C19: CABLETYPEC1MW | D19: 1144172936 | 2524776910 | E19: Cable Usb Para Carga Y Datos Tipo C De 1 Mt Blanco | F19: 0 | G19: 10 | H19: 77 | I19: =ROUND($H19/30,2) -> 2.57 | J19: =IF($Z19="CENSURADO",ROUND($T19/MAX($V19,3),2),ROUND($T19/$G$3,2)) -> 5.32 | K19: =ROUNDUP($J19*$C$3*7,0) -> 112 | L19: =MAX(0,$K19-$F19-$G19) -> 102 | M19: 3966 | N19: 35 | O19: =$M19+$N19 -> 4001 | P19: =MIN($L19,$O19) -> 102 | Q19: Activa | R19: 1 | S19: Pequeño | T19: 101 | U19: 10 | V19: 19 | W19: 5 | X19: 50 | Y19: =IF($X19=0,"",ROUND($H19/$X19,2)) -> 1.54 | Z19: =IF(AND($F19=0,$T19>=5,$W19>=3),"CENSURADO",IF(AND($Y19<>"",$Y19>=3,$T19>=10),"CENSURADO",IF($T19=0,"SIN DATO","CONFIABLE"))) -> CENSURADO | AA19: =IF($I19=0,"",ROUND($J19/MAX($I19,0.01),2)) -> 2.07 | AB19: =IF($J19<=0,"",ROUND(($F19+$G19)/$J19,0)) -> 2 | AC19: =IF($AB19="","",$J$3+$AB19) -> 46247 | AD19: 0 | AE19: 0 | AF19: 0 | AG19: =IF($AF19=0,"",MAX(0,180-$AE19)) | AH19: 0 | AI19: =IF($AF19=0,"",$AF19*$Q$3-$AF19*$N$3) | AJ19: 0.4 | AK19: =ROUND($F19*$AJ19,0) -> 0 | AL19: =IF(AND($F19=0,$T19>0,$O19=0),"QUIEBRE Y SIN STOCK PARA ENVIAR",IF(AND($F19=0,$T19>0),"QUIEBRE",IF($F19=0,"SIN STOCK SIN DEMANDA",IF(AND($AF19>0,$AG19<>"",OR($AB19="",$AB19>$AG19)),"STOCK VIEJO EN RIESGO",IF(AND($T19=0,$H19=0),"SIN ROTACION",IF($AB19="","-",IF($AB19<14,"REPONER",IF($AB19>84,"SOBRE-STOCK","EN RANGO")))))))) -> QUIEBRE
A20: IT | B20: RFFM10562 | C20: TVS-ARM-14-42I-200X200-V3 | D20: 2094731522 | E20: Soporte Tv Led Lcd Móvil Largo Simple De 14 A 42 Pulgadas Negro | F20: 0 | G20: 10 | H20: 73 | I20: =ROUND($H20/30,2) -> 2.43 | J20: =IF($Z20="CENSURADO",ROUND($T20/MAX($V20,3),2),ROUND($T20/$G$3,2)) -> 4.13 | K20: =ROUNDUP($J20*$C$3*7,0) -> 87 | L20: =MAX(0,$K20-$F20-$G20) -> 77 | M20: 1221 | N20: 15 | O20: =$M20+$N20 -> 1236 | P20: =MIN($L20,$O20) -> 77 | Q20: Activa | R20: 1 | S20: Mediano | T20: 95 | U20: 16 | V20: 23 | W20: 3 | X20: 54 | Y20: =IF($X20=0,"",ROUND($H20/$X20,2)) -> 1.35 | Z20: =IF(AND($F20=0,$T20>=5,$W20>=3),"CENSURADO",IF(AND($Y20<>"",$Y20>=3,$T20>=10),"CENSURADO",IF($T20=0,"SIN DATO","CONFIABLE"))) -> CENSURADO | AA20: =IF($I20=0,"",ROUND($J20/MAX($I20,0.01),2)) -> 1.7 | AB20: =IF($J20<=0,"",ROUND(($F20+$G20)/$J20,0)) -> 2 | AC20: =IF($AB20="","",$J$3+$AB20) -> 46247 | AD20: 0 | AE20: 0 | AF20: 0 | AG20: =IF($AF20=0,"",MAX(0,180-$AE20)) | AH20: 0 | AI20: =IF($AF20=0,"",$AF20*$Q$3-$AF20*$N$3) | AJ20: 3.16 | AK20: =ROUND($F20*$AJ20,0) -> 0 | AL20: =IF(AND($F20=0,$T20>0,$O20=0),"QUIEBRE Y SIN STOCK PARA ENVIAR",IF(AND($F20=0,$T20>0),"QUIEBRE",IF($F20=0,"SIN STOCK SIN DEMANDA",IF(AND($AF20>0,$AG20<>"",OR($AB20="",$AB20>$AG20)),"STOCK VIEJO EN RIESGO",IF(AND($T20=0,$H20=0),"SIN ROTACION",IF($AB20="","-",IF($AB20<14,"REPONER",IF($AB20>84,"SOBRE-STOCK","EN RANGO")))))))) -> QUIEBRE
A21: IT | B21: EYBK93102 | C21: CUTTERROTA-45MM | D21: 2012428570 | 2683194688 | E21: Cutter Rotativo De 45mm De Diámetro Para Corte Recto | F21: 0 | G21: 30 | H21: 44 | I21: =ROUND($H21/30,2) -> 1.47 | J21: =IF($Z21="CENSURADO",ROUND($T21/MAX($V21,3),2),ROUND($T21/$G$3,2)) -> 2.53 | K21: =ROUNDUP($J21*$C$3*7,0) -> 54 | L21: =MAX(0,$K21-$F21-$G21) -> 24 | M21: 677 | N21: 138 | O21: =$M21+$N21 -> 815 | P21: =MIN($L21,$O21) -> 24 | Q21: Activa | R21: 1 | S21: Pequeño | T21: 81 | U21: 28 | V21: 31 | W21: 0 | X21: 23 | Y21: =IF($X21=0,"",ROUND($H21/$X21,2)) -> 1.91 | Z21: =IF(AND($F21=0,$T21>=5,$W21>=3),"CENSURADO",IF(AND($Y21<>"",$Y21>=3,$T21>=10),"CENSURADO",IF($T21=0,"SIN DATO","CONFIABLE"))) -> CONFIABLE | AA21: =IF($I21=0,"",ROUND($J21/MAX($I21,0.01),2)) -> 1.72 | AB21: =IF($J21<=0,"",ROUND(($F21+$G21)/$J21,0)) -> 12 | AC21: =IF($AB21="","",$J$3+$AB21) -> 46257 | AD21: 0 | AE21: 0 | AF21: 0 | AG21: =IF($AF21=0,"",MAX(0,180-$AE21)) | AH21: 0 | AI21: =IF($AF21=0,"",$AF21*$Q$3-$AF21*$N$3) | AJ21: 1.44 | AK21: =ROUND($F21*$AJ21,0) -> 0 | AL21: =IF(AND($F21=0,$T21>0,$O21=0),"QUIEBRE Y SIN STOCK PARA ENVIAR",IF(AND($F21=0,$T21>0),"QUIEBRE",IF($F21=0,"SIN STOCK SIN DEMANDA",IF(AND($AF21>0,$AG21<>"",OR($AB21="",$AB21>$AG21)),"STOCK VIEJO EN RIESGO",IF(AND($T21=0,$H21=0),"SIN ROTACION",IF($AB21="","-",IF($AB21<14,"REPONER",IF($AB21>84,"SOBRE-STOCK","EN RANGO")))))))) -> QUIEBRE
A22: IT | B22: LKLY99491 | C22: PAPERDFG220A4-20 | D22: 1827462704 | E22: Papel Doble Faz Glossy A4 220 Grs Pack X20 Hojas Blanco | F22: 0 | G22: 0 | H22: 50 | I22: =ROUND($H22/30,2) -> 1.67 | J22: =IF($Z22="CENSURADO",ROUND($T22/MAX($V22,3),2),ROUND($T22/$G$3,2)) -> 5.2 | K22: =ROUNDUP($J22*$C$3*7,0) -> 110 | L22: =MAX(0,$K22-$F22-$G22) -> 110 | M22: 0 | N22: 0 | O22: =$M22+$N22 -> 0 | P22: =MIN($L22,$O22) -> 0 | R22: 2 | S22: Mediano | T22: 78 | U22: 13 | V22: 15 | W22: 17 | X22: 10 | Y22: =IF($X22=0,"",ROUND($H22/$X22,2)) -> 5 | Z22: =IF(AND($F22=0,$T22>=5,$W22>=3),"CENSURADO",IF(AND($Y22<>"",$Y22>=3,$T22>=10),"CENSURADO",IF($T22=0,"SIN DATO","CONFIABLE"))) -> CENSURADO | AA22: =IF($I22=0,"",ROUND($J22/MAX($I22,0.01),2)) -> 3.11 | AB22: =IF($J22<=0,"",ROUND(($F22+$G22)/$J22,0)) -> 0 | AC22: =IF($AB22="","",$J$3+$AB22) -> 46245 | AD22: 0 | AE22: 0 | AF22: 0 | AG22: =IF($AF22=0,"",MAX(0,180-$AE22)) | AH22: 0 | AI22: =IF($AF22=0,"",$AF22*$Q$3-$AF22*$N$3) | AJ22: 0.61 | AK22: =ROUND($F22*$AJ22,0) -> 0 | AL22: =IF(AND($F22=0,$T22>0,$O22=0),"QUIEBRE Y SIN STOCK PARA ENVIAR",IF(AND($F22=0,$T22>0),"QUIEBRE",IF($F22=0,"SIN STOCK SIN DEMANDA",IF(AND($AF22>0,$AG22<>"",OR($AB22="",$AB22>$AG22)),"STOCK VIEJO EN RIESGO",IF(AND($T22=0,$H22=0),"SIN ROTACION",IF($AB22="","-",IF($AB22<14,"REPONER",IF($AB22>84,"SOBRE-STOCK","EN RANGO")))))))) -> QUIEBRE Y SIN STOCK PARA ENVIAR
A23: IT | B23: PDOM19535 | C23: TVS-ARM-14-42I-200X200 | D23: 1458409112 | E23: Soporte Global Tvs-arm-14-42i-200x200 Tv Led Lcd Con Brazo Vesa 200x200 Color Ne | F23: 3 | G23: 10 | H23: 50 | I23: =ROUND($H23/30,2) -> 1.67 | J23: =IF($Z23="CENSURADO",ROUND($T23/MAX($V23,3),2),ROUND($T23/$G$3,2)) -> 2.44 | K23: =ROUNDUP($J23*$C$3*7,0) -> 52 | L23: =MAX(0,$K23-$F23-$G23) -> 39 | M23: 1470 | N23: 4 | O23: =$M23+$N23 -> 1474 | P23: =MIN($L23,$O23) -> 39 | Q23: Activa | R23: 1 | S23: Mediano | T23: 78 | U23: 24 | V23: 28 | W23: 0 | X23: 33 | Y23: =IF($X23=0,"",ROUND($H23/$X23,2)) -> 1.52 | Z23: =IF(AND($F23=0,$T23>=5,$W23>=3),"CENSURADO",IF(AND($Y23<>"",$Y23>=3,$T23>=10),"CENSURADO",IF($T23=0,"SIN DATO","CONFIABLE"))) -> CONFIABLE | AA23: =IF($I23=0,"",ROUND($J23/MAX($I23,0.01),2)) -> 1.46 | AB23: =IF($J23<=0,"",ROUND(($F23+$G23)/$J23,0)) -> 5 | AC23: =IF($AB23="","",$J$3+$AB23) -> 46250 | AD23: 0 | AE23: 0 | AF23: 0 | AG23: =IF($AF23=0,"",MAX(0,180-$AE23)) | AH23: 0 | AI23: =IF($AF23=0,"",$AF23*$Q$3-$AF23*$N$3) | AJ23: 3.84 | AK23: =ROUND($F23*$AJ23,0) -> 12 | AL23: =IF(AND($F23=0,$T23>0,$O23=0),"QUIEBRE Y SIN STOCK PARA ENVIAR",IF(AND($F23=0,$T23>0),"QUIEBRE",IF($F23=0,"SIN STOCK SIN DEMANDA",IF(AND($AF23>0,$AG23<>"",OR($AB23="",$AB23>$AG23)),"STOCK VIEJO EN RIESGO",IF(AND($T23=0,$H23=0),"SIN ROTACION",IF($AB23="","-",IF($AB23<14,"REPONER",IF($AB23>84,"SOBRE-STOCK","EN RANGO")))))))) -> REPONER
A24: IT | B24: FBAY21200 | C24: MLTD111LCOMPV2 | D24: 612395687 | E24: Toner Alternativo Para Samsung 111l Mlt D111l M2020w M2070w Negro | F24: 4 | G24: 0 | H24: 20 | I24: =ROUND($H24/30,2) -> 0.67 | J24: =IF($Z24="CENSURADO",ROUND($T24/MAX($V24,3),2),ROUND($T24/$G$3,2)) -> 2.25 | K24: =ROUNDUP($J24*$C$3*7,0) -> 48 | L24: =MAX(0,$K24-$F24-$G24) -> 44 | M24: 726 | N24: 2616 | O24: =$M24+$N24 -> 3342 | P24: =MIN($L24,$O24) -> 44 | Q24: Activa | R24: 1 | S24: Mediano | T24: 72 | U24: 21 | V24: 29 | W24: 0 | X24: 19 | Y24: =IF($X24=0,"",ROUND($H24/$X24,2)) -> 1.05 | Z24: =IF(AND($F24=0,$T24>=5,$W24>=3),"CENSURADO",IF(AND($Y24<>"",$Y24>=3,$T24>=10),"CENSURADO",IF($T24=0,"SIN DATO","CONFIABLE"))) -> CONFIABLE | AA24: =IF($I24=0,"",ROUND($J24/MAX($I24,0.01),2)) -> 3.36 | AB24: =IF($J24<=0,"",ROUND(($F24+$G24)/$J24,0)) -> 2 | AC24: =IF($AB24="","",$J$3+$AB24) -> 46247 | AD24: 0 | AE24: 0 | AF24: 0 | AG24: =IF($AF24=0,"",MAX(0,180-$AE24)) | AH24: 0 | AI24: =IF($AF24=0,"",$AF24*$Q$3-$AF24*$N$3) | AJ24: 2.66 | AK24: =ROUND($F24*$AJ24,0) -> 11 | AL24: =IF(AND($F24=0,$T24>0,$O24=0),"QUIEBRE Y SIN STOCK PARA ENVIAR",IF(AND($F24=0,$T24>0),"QUIEBRE",IF($F24=0,"SIN STOCK SIN DEMANDA",IF(AND($AF24>0,$AG24<>"",OR($AB24="",$AB24>$AG24)),"STOCK VIEJO EN RIESGO",IF(AND($T24=0,$H24=0),"SIN ROTACION",IF($AB24="","-",IF($AB24<14,"REPONER",IF($AB24>84,"SOBRE-STOCK","EN RANGO")))))))) -> REPONER
A25: IT | B25: COCF22823 | C25: X2 EMERLIGHT-30LED | D25: 1607512661 | E25: Pack De 2 Luces Luz De Emergencia 30 Leds Bateria Recargable Seguridad - Marca G | F25: 0 | G25: 0 | H25: 42 | I25: =ROUND($H25/30,2) -> 1.4 | J25: =IF($Z25="CENSURADO",ROUND($T25/MAX($V25,3),2),ROUND($T25/$G$3,2)) -> 1.72 | K25: =ROUNDUP($J25*$C$3*7,0) -> 37 | L25: =MAX(0,$K25-$F25-$G25) -> 37 | M25: 0 | N25: 0 | O25: =$M25+$N25 -> 0 | P25: =MIN($L25,$O25) -> 0 | Q25: Activa | R25: 1 | S25: Pequeño | T25: 55 | U25: 24 | V25: 32 | W25: 0 | X25: 15 | Y25: =IF($X25=0,"",ROUND($H25/$X25,2)) -> 2.8 | Z25: =IF(AND($F25=0,$T25>=5,$W25>=3),"CENSURADO",IF(AND($Y25<>"",$Y25>=3,$T25>=10),"CENSURADO",IF($T25=0,"SIN DATO","CONFIABLE"))) -> CONFIABLE | AA25: =IF($I25=0,"",ROUND($J25/MAX($I25,0.01),2)) -> 1.23 | AB25: =IF($J25<=0,"",ROUND(($F25+$G25)/$J25,0)) -> 0 | AC25: =IF($AB25="","",$J$3+$AB25) -> 46245 | AD25: 0 | AE25: 0 | AF25: 0 | AG25: =IF($AF25=0,"",MAX(0,180-$AE25)) | AH25: 0 | AI25: =IF($AF25=0,"",$AF25*$Q$3-$AF25*$N$3) | AJ25: 0 | AK25: =ROUND($F25*$AJ25,0) -> 0 | AL25: =IF(AND($F25=0,$T25>0,$O25=0),"QUIEBRE Y SIN STOCK PARA ENVIAR",IF(AND($F25=0,$T25>0),"QUIEBRE",IF($F25=0,"SIN STOCK SIN DEMANDA",IF(AND($AF25>0,$AG25<>"",OR($AB25="",$AB25>$AG25)),"STOCK VIEJO EN RIESGO",IF(AND($T25=0,$H25=0),"SIN ROTACION",IF($AB25="","-",IF($AB25<14,"REPONER",IF($AB25>84,"SOBRE-STOCK","EN RANGO")))))))) -> QUIEBRE Y SIN STOCK PARA ENVIAR
A26: IT | B26: GEQW17118 | C26: CF230ACOMP | D26: 708048237 | E26: Toner Alternativo Para Cf 230a M203dn M227fdw Con Chip Negro | F26: 18 | G26: 0 | H26: 12 | I26: =ROUND($H26/30,2) -> 0.4 | J26: =IF($Z26="CENSURADO",ROUND($T26/MAX($V26,3),2),ROUND($T26/$G$3,2)) -> 1.53 | K26: =ROUNDUP($J26*$C$3*7,0) -> 33 | L26: =MAX(0,$K26-$F26-$G26) -> 15 | M26: 525 | N26: 1016 | O26: =$M26+$N26 -> 1541 | P26: =MIN($L26,$O26) -> 15 | Q26: Activa | R26: 1 | S26: Mediano | T26: 49 | U26: 9 | V26: 24 | W26: 6 | X26: 25 | Y26: =IF($X26=0,"",ROUND($H26/$X26,2)) -> 0.48 | Z26: =IF(AND($F26=0,$T26>=5,$W26>=3),"CENSURADO",IF(AND($Y26<>"",$Y26>=3,$T26>=10),"CENSURADO",IF($T26=0,"SIN DATO","CONFIABLE"))) -> CONFIABLE | AA26: =IF($I26=0,"",ROUND($J26/MAX($I26,0.01),2)) -> 3.83 | AB26: =IF($J26<=0,"",ROUND(($F26+$G26)/$J26,0)) -> 12 | AC26: =IF($AB26="","",$J$3+$AB26) -> 46257 | AD26: 0 | AE26: 205 | AF26: 1 | AG26: =IF($AF26=0,"",MAX(0,180-$AE26)) -> 0 | AH26: 45320 | AI26: =IF($AF26=0,"",$AF26*$Q$3-$AF26*$N$3) -> 4015 | AJ26: 2.14 | AK26: =ROUND($F26*$AJ26,0) -> 39 | AL26: =IF(AND($F26=0,$T26>0,$O26=0),"QUIEBRE Y SIN STOCK PARA ENVIAR",IF(AND($F26=0,$T26>0),"QUIEBRE",IF($F26=0,"SIN STOCK SIN DEMANDA",IF(AND($AF26>0,$AG26<>"",OR($AB26="",$AB26>$AG26)),"STOCK VIEJO EN RIESGO",IF(AND($T26=0,$H26=0),"SIN ROTACION",IF($AB26="","-",IF($AB26<14,"REPONER",IF($AB26>84,"SOBRE-STOCK","EN RANGO")))))))) -> STOCK VIEJO EN RIESGO
A27: IT | B27: UIUW05655 | C27: 408161COMP | D27: 1431642515 | 719603965 | E27: Toner Alternativo Para Ricoh 408161 Sp377dnwx 377sfnwx Negro | F27: 0 | G27: 0 | H27: 40 | I27: =ROUND($H27/30,2) -> 1.33 | J27: =IF($Z27="CENSURADO",ROUND($T27/MAX($V27,3),2),ROUND($T27/$G$3,2)) -> 2 | K27: =ROUNDUP($J27*$C$3*7,0) -> 42 | L27: =MAX(0,$K27-$F27-$G27) -> 42 | M27: 10 | N27: 0 | O27: =$M27+$N27 -> 10 | P27: =MIN($L27,$O27) -> 10 | R27: 1 | S27: Mediano | T27: 46 | U27: 10 | V27: 23 | W27: 6 | X27: 14 | Y27: =IF($X27=0,"",ROUND($H27/$X27,2)) -> 2.86 | Z27: =IF(AND($F27=0,$T27>=5,$W27>=3),"CENSURADO",IF(AND($Y27<>"",$Y27>=3,$T27>=10),"CENSURADO",IF($T27=0,"SIN DATO","CONFIABLE"))) -> CENSURADO | AA27: =IF($I27=0,"",ROUND($J27/MAX($I27,0.01),2)) -> 1.5 | AB27: =IF($J27<=0,"",ROUND(($F27+$G27)/$J27,0)) -> 0 | AC27: =IF($AB27="","",$J$3+$AB27) -> 46245 | AD27: 0 | AE27: 170 | AF27: 51 | AG27: =IF($AF27=0,"",MAX(0,180-$AE27)) -> 10 | AH27: 23970 | AI27: =IF($AF27=0,"",$AF27*$Q$3-$AF27*$N$3) -> 204765 | AJ27: 5.95 | AK27: =ROUND($F27*$AJ27,0) -> 0 | AL27: =IF(AND($F27=0,$T27>0,$O27=0),"QUIEBRE Y SIN STOCK PARA ENVIAR",IF(AND($F27=0,$T27>0),"QUIEBRE",IF($F27=0,"SIN STOCK SIN DEMANDA",IF(AND($AF27>0,$AG27<>"",OR($AB27="",$AB27>$AG27)),"STOCK VIEJO EN RIESGO",IF(AND($T27=0,$H27=0),"SIN ROTACION",IF($AB27="","-",IF($AB27<14,"REPONER",IF($AB27>84,"SOBRE-STOCK","EN RANGO")))))))) -> QUIEBRE
A28: IT | B28: WIZE38075 | C28: CALCU-12D-1200V | D28: 1420753775 | 826774371 | E28: Calculadora Global 12 Digitos, Mod. 1200v Metalizada Metalizado | F28: 0 | G28: 10 | H28: 30 | I28: =ROUND($H28/30,2) -> 1 | J28: =IF($Z28="CENSURADO",ROUND($T28/MAX($V28,3),2),ROUND($T28/$G$3,2)) -> 1.41 | K28: =ROUNDUP($J28*$C$3*7,0) -> 30 | L28: =MAX(0,$K28-$F28-$G28) -> 20 | M28: 1799 | N28: 1295 | O28: =$M28+$N28 -> 3094 | P28: =MIN($L28,$O28) -> 20 | Q28: Activa | R28: 1 | S28: Mediano | T28: 45 | U28: 10 | V28: 20 | W28: 2 | X28: 20 | Y28: =IF($X28=0,"",ROUND($H28/$X28,2)) -> 1.5 | Z28: =IF(AND($F28=0,$T28>=5,$W28>=3),"CENSURADO",IF(AND($Y28<>"",$Y28>=3,$T28>=10),"CENSURADO",IF($T28=0,"SIN DATO","CONFIABLE"))) -> CONFIABLE | AA28: =IF($I28=0,"",ROUND($J28/MAX($I28,0.01),2)) -> 1.41 | AB28: =IF($J28<=0,"",ROUND(($F28+$G28)/$J28,0)) -> 7 | AC28: =IF($AB28="","",$J$3+$AB28) -> 46252 | AD28: 0 | AE28: 0 | AF28: 0 | AG28: =IF($AF28=0,"",MAX(0,180-$AE28)) | AH28: 0 | AI28: =IF($AF28=0,"",$AF28*$Q$3-$AF28*$N$3) | AJ28: 2.16 | AK28: =ROUND($F28*$AJ28,0) -> 0 | AL28: =IF(AND($F28=0,$T28>0,$O28=0),"QUIEBRE Y SIN STOCK PARA ENVIAR",IF(AND($F28=0,$T28>0),"QUIEBRE",IF($F28=0,"SIN STOCK SIN DEMANDA",IF(AND($AF28>0,$AG28<>"",OR($AB28="",$AB28>$AG28)),"STOCK VIEJO EN RIESGO",IF(AND($T28=0,$H28=0),"SIN ROTACION",IF($AB28="","-",IF($AB28<14,"REPONER",IF($AB28>84,"SOBRE-STOCK","EN RANGO")))))))) -> QUIEBRE
A29: IT | B29: FZLX96684 | C29: PROJS-ARM-UNIV-430-650MM | D29: 1377104819 | 1611159705 | E29: Soporte Proyector Universal Brazo Extensible De 430 A 650mm Blanco | F29: 0 | G29: 20 | H29: 26 | I29: =ROUND($H29/30,2) -> 0.87 | J29: =IF($Z29="CENSURADO",ROUND($T29/MAX($V29,3),2),ROUND($T29/$G$3,2)) -> 1.45 | K29: =ROUNDUP($J29*$C$3*7,0) -> 31 | L29: =MAX(0,$K29-$F29-$G29) -> 11 | M29: 422 | N29: 18 | O29: =$M29+$N29 -> 440 | P29: =MIN($L29,$O29) -> 11 | Q29: Activa | R29: 1 | S29: Mediano | T29: 42 | U29: 20 | V29: 29 | W29: 1 | X29: 6 | Y29: =IF($X29=0,"",ROUND($H29/$X29,2)) -> 4.33 | Z29: =IF(AND($F29=0,$T29>=5,$W29>=3),"CENSURADO",IF(AND($Y29<>"",$Y29>=3,$T29>=10),"CENSURADO",IF($T29=0,"SIN DATO","CONFIABLE"))) -> CENSURADO | AA29: =IF($I29=0,"",ROUND($J29/MAX($I29,0.01),2)) -> 1.67 | AB29: =IF($J29<=0,"",ROUND(($F29+$G29)/$J29,0)) -> 14 | AC29: =IF($AB29="","",$J$3+$AB29) -> 46259 | AD29: 0 | AE29: 0 | AF29: 0 | AG29: =IF($AF29=0,"",MAX(0,180-$AE29)) | AH29: 0 | AI29: =IF($AF29=0,"",$AF29*$Q$3-$AF29*$N$3) | AJ29: 6.83 | AK29: =ROUND($F29*$AJ29,0) -> 0 | AL29: =IF(AND($F29=0,$T29>0,$O29=0),"QUIEBRE Y SIN STOCK PARA ENVIAR",IF(AND($F29=0,$T29>0),"QUIEBRE",IF($F29=0,"SIN STOCK SIN DEMANDA",IF(AND($AF29>0,$AG29<>"",OR($AB29="",$AB29>$AG29)),"STOCK VIEJO EN RIESGO",IF(AND($T29=0,$H29=0),"SIN ROTACION",IF($AB29="","-",IF($AB29<14,"REPONER",IF($AB29>84,"SOBRE-STOCK","EN RANGO")))))))) -> QUIEBRE
A30: IT | B30: KNPR20887 | C30: TN450COMP | D30: 628912421 | E30: Toner Alternativo Para Brother Tn410 Tn450 Hl 2130 Dcp 7055 | F30: 0 | G30: 0 | H30: 0 | I30: =ROUND($H30/30,2) -> 0 | J30: =IF($Z30="CENSURADO",ROUND($T30/MAX($V30,3),2),ROUND($T30/$G$3,2)) -> 2.16 | K30: =ROUNDUP($J30*$C$3*7,0) -> 46 | L30: =MAX(0,$K30-$F30-$G30) -> 46 | M30: 15 | N30: 0 | O30: =$M30+$N30 -> 15 | P30: =MIN($L30,$O30) -> 15 | Q30: Inactiva | R30: 1 | S30: Mediano | T30: 41 | U30: 11 | V30: 19 | W30: 12 | X30: 0 | Y30: =IF($X30=0,"",ROUND($H30/$X30,2)) | Z30: =IF(AND($F30=0,$T30>=5,$W30>=3),"CENSURADO",IF(AND($Y30<>"",$Y30>=3,$T30>=10),"CENSURADO",IF($T30=0,"SIN DATO","CONFIABLE"))) -> CENSURADO | AA30: =IF($I30=0,"",ROUND($J30/MAX($I30,0.01),2)) | AB30: =IF($J30<=0,"",ROUND(($F30+$G30)/$J30,0)) -> 0 | AC30: =IF($AB30="","",$J$3+$AB30) -> 46245 | AD30: 0 | AE30: 0 | AF30: 0 | AG30: =IF($AF30=0,"",MAX(0,180-$AE30)) | AH30: 0 | AI30: =IF($AF30=0,"",$AF30*$Q$3-$AF30*$N$3) | AJ30: 2.37 | AK30: =ROUND($F30*$AJ30,0) -> 0 | AL30: =IF(AND($F30=0,$T30>0,$O30=0),"QUIEBRE Y SIN STOCK PARA ENVIAR",IF(AND($F30=0,$T30>0),"QUIEBRE",IF($F30=0,"SIN STOCK SIN DEMANDA",IF(AND($AF30>0,$AG30<>"",OR($AB30="",$AB30>$AG30)),"STOCK VIEJO EN RIESGO",IF(AND($T30=0,$H30=0),"SIN ROTACION",IF($AB30="","-",IF($AB30<14,"REPONER",IF($AB30>84,"SOBRE-STOCK","EN RANGO")))))))) -> QUIEBRE
A31: IT | B31: NJLU22691 | C31: TSHIRTGUIDERULE-AIO | D31: 1480466439 | E31: Regla Guía Para Centrar Sublimación De Remeras | F31: 0 | G31: 0 | H31: 38 | I31: =ROUND($H31/30,2) -> 1.27 | J31: =IF($Z31="CENSURADO",ROUND($T31/MAX($V31,3),2),ROUND($T31/$G$3,2)) -> 1.41 | K31: =ROUNDUP($J31*$C$3*7,0) -> 30 | L31: =MAX(0,$K31-$F31-$G31) -> 30 | M31: 1 | N31: -2 | O31: =$M31+$N31 -> -1 | P31: =MIN($L31,$O31) -> -1 | R31: 1 | S31: Mediano | T31: 38 | U31: 19 | V31: 27 | W31: 4 | X31: 18 | Y31: =IF($X31=0,"",ROUND($H31/$X31,2)) -> 2.11 | Z31: =IF(AND($F31=0,$T31>=5,$W31>=3),"CENSURADO",IF(AND($Y31<>"",$Y31>=3,$T31>=10),"CENSURADO",IF($T31=0,"SIN DATO","CONFIABLE"))) -> CENSURADO | AA31: =IF($I31=0,"",ROUND($J31/MAX($I31,0.01),2)) -> 1.11 | AB31: =IF($J31<=0,"",ROUND(($F31+$G31)/$J31,0)) -> 0 | AC31: =IF($AB31="","",$J$3+$AB31) -> 46245 | AD31: 0 | AE31: 0 | AF31: 0 | AG31: =IF($AF31=0,"",MAX(0,180-$AE31)) | AH31: 0 | AI31: =IF($AF31=0,"",$AF31*$Q$3-$AF31*$N$3) | AJ31: 1.67 | AK31: =ROUND($F31*$AJ31,0) -> 0 | AL31: =IF(AND($F31=0,$T31>0,$O31=0),"QUIEBRE Y SIN STOCK PARA ENVIAR",IF(AND($F31=0,$T31>0),"QUIEBRE",IF($F31=0,"SIN STOCK SIN DEMANDA",IF(AND($AF31>0,$AG31<>"",OR($AB31="",$AB31>$AG31)),"STOCK VIEJO EN RIESGO",IF(AND($T31=0,$H31=0),"SIN ROTACION",IF($AB31="","-",IF($AB31<14,"REPONER",IF($AB31>84,"SOBRE-STOCK","EN RANGO")))))))) -> QUIEBRE
A32: IT | B32: UMOI01514 | C32: ESPATULA-UA02S | D32: 1124089712 | E32: Espatula Para Impresión Ua02s | F32: 24 | G32: 0 | H32: 24 | I32: =ROUND($H32/30,2) -> 0.8 | J32: =IF($Z32="CENSURADO",ROUND($T32/MAX($V32,3),2),ROUND($T32/$G$3,2)) -> 1.19 | K32: =ROUNDUP($J32*$C$3*7,0) -> 25 | L32: =MAX(0,$K32-$F32-$G32) -> 1 | M32: 4324 | N32: 219 | O32: =$M32+$N32 -> 4543 | P32: =MIN($L32,$O32) -> 1 | Q32: Activa | R32: 1 | S32: Pequeño | T32: 38 | U32: 18 | V32: 29 | W32: 1 | X32: 40 | Y32: =IF($X32=0,"",ROUND($H32/$X32,2)) -> 0.6 | Z32: =IF(AND($F32=0,$T32>=5,$W32>=3),"CENSURADO",IF(AND($Y32<>"",$Y32>=3,$T32>=10),"CENSURADO",IF($T32=0,"SIN DATO","CONFIABLE"))) -> CONFIABLE | AA32: =IF($I32=0,"",ROUND($J32/MAX($I32,0.01),2)) -> 1.49 | AB32: =IF($J32<=0,"",ROUND(($F32+$G32)/$J32,0)) -> 20 | AC32: =IF($AB32="","",$J$3+$AB32) -> 46265 | AD32: 0 | AE32: 0 | AF32: 0 | AG32: =IF($AF32=0,"",MAX(0,180-$AE32)) | AH32: 0 | AI32: =IF($AF32=0,"",$AF32*$Q$3-$AF32*$N$3) | AJ32: 0.46 | AK32: =ROUND($F32*$AJ32,0) -> 11 | AL32: =IF(AND($F32=0,$T32>0,$O32=0),"QUIEBRE Y SIN STOCK PARA ENVIAR",IF(AND($F32=0,$T32>0),"QUIEBRE",IF($F32=0,"SIN STOCK SIN DEMANDA",IF(AND($AF32>0,$AG32<>"",OR($AB32="",$AB32>$AG32)),"STOCK VIEJO EN RIESGO",IF(AND($T32=0,$H32=0),"SIN ROTACION",IF($AB32="","-",IF($AB32<14,"REPONER",IF($AB32>84,"SOBRE-STOCK","EN RANGO")))))))) -> EN RANGO
A33: IT | B33: CPKK59309 | C33: EPGMR035BLACK | D33: 1130272651 | E33: Auricular Epgmr035 Gaming Con Microfono Stereo Negro Negro | F33: 0 | G33: 0 | H33: 26 | I33: =ROUND($H33/30,2) -> 0.87 | J33: =IF($Z33="CENSURADO",ROUND($T33/MAX($V33,3),2),ROUND($T33/$G$3,2)) -> 1.38 | K33: =ROUNDUP($J33*$C$3*7,0) -> 29 | L33: =MAX(0,$K33-$F33-$G33) -> 29 | M33: 540 | N33: 78 | O33: =$M33+$N33 -> 618 | P33: =MIN($L33,$O33) -> 29 | Q33: Activa | R33: 1 | S33: Pequeño | T33: 36 | U33: 14 | V33: 26 | W33: 5 | X33: 8 | Y33: =IF($X33=0,"",ROUND($H33/$X33,2)) -> 3.25 | Z33: =IF(AND($F33=0,$T33>=5,$W33>=3),"CENSURADO",IF(AND($Y33<>"",$Y33>=3,$T33>=10),"CENSURADO",IF($T33=0,"SIN DATO","CONFIABLE"))) -> CENSURADO | AA33: =IF($I33=0,"",ROUND($J33/MAX($I33,0.01),2)) -> 1.59 | AB33: =IF($J33<=0,"",ROUND(($F33+$G33)/$J33,0)) -> 0 | AC33: =IF($AB33="","",$J$3+$AB33) -> 46245 | AD33: 0 | AE33: 0 | AF33: 0 | AG33: =IF($AF33=0,"",MAX(0,180-$AE33)) | AH33: 0 | AI33: =IF($AF33=0,"",$AF33*$Q$3-$AF33*$N$3) | AJ33: 0 | AK33: =ROUND($F33*$AJ33,0) -> 0 | AL33: =IF(AND($F33=0,$T33>0,$O33=0),"QUIEBRE Y SIN STOCK PARA ENVIAR",IF(AND($F33=0,$T33>0),"QUIEBRE",IF($F33=0,"SIN STOCK SIN DEMANDA",IF(AND($AF33>0,$AG33<>"",OR($AB33="",$AB33>$AG33)),"STOCK VIEJO EN RIESGO",IF(AND($T33=0,$H33=0),"SIN ROTACION",IF($AB33="","-",IF($AB33<14,"REPONER",IF($AB33>84,"SOBRE-STOCK","EN RANGO")))))))) -> QUIEBRE
A34: IT | B34: YNEY91417 | C34: KMG20BKCOMBOWLS | D34: 3415097238 | 674608017 | E34: Kit Teclado + Mouse Inalambrico Wireless Smart Pc Notebook Negro | F34: 0 | G34: 0 | H34: 20 | I34: =ROUND($H34/30,2) -> 0.67 | J34: =IF($Z34="CENSURADO",ROUND($T34/MAX($V34,3),2),ROUND($T34/$G$3,2)) -> 1.09 | K34: =ROUNDUP($J34*$C$3*7,0) -> 23 | L34: =MAX(0,$K34-$F34-$G34) -> 23 | M34: 2756 | N34: 132 | O34: =$M34+$N34 -> 2888 | P34: =MIN($L34,$O34) -> 23 | Q34: Activa | R34: 2 | S34: Grande | T34: 35 | U34: 14 | V34: 27 | W34: 2 | X34: 13 | Y34: =IF($X34=0,"",ROUND($H34/$X34,2)) -> 1.54 | Z34: =IF(AND($F34=0,$T34>=5,$W34>=3),"CENSURADO",IF(AND($Y34<>"",$Y34>=3,$T34>=10),"CENSURADO",IF($T34=0,"SIN DATO","CONFIABLE"))) -> CONFIABLE | AA34: =IF($I34=0,"",ROUND($J34/MAX($I34,0.01),2)) -> 1.63 | AB34: =IF($J34<=0,"",ROUND(($F34+$G34)/$J34,0)) -> 0 | AC34: =IF($AB34="","",$J$3+$AB34) -> 46245 | AD34: 0 | AE34: 0 | AF34: 0 | AG34: =IF($AF34=0,"",MAX(0,180-$AE34)) | AH34: 0 | AI34: =IF($AF34=0,"",$AF34*$Q$3-$AF34*$N$3) | AJ34: 5.52 | AK34: =ROUND($F34*$AJ34,0) -> 0 | AL34: =IF(AND($F34=0,$T34>0,$O34=0),"QUIEBRE Y SIN STOCK PARA ENVIAR",IF(AND($F34=0,$T34>0),"QUIEBRE",IF($F34=0,"SIN STOCK SIN DEMANDA",IF(AND($AF34>0,$AG34<>"",OR($AB34="",$AB34>$AG34)),"STOCK VIEJO EN RIESGO",IF(AND($T34=0,$H34=0),"SIN ROTACION",IF($AB34="","-",IF($AB34<14,"REPONER",IF($AB34>84,"SOBRE-STOCK","EN RANGO")))))))) -> QUIEBRE
A35: IT | B35: NDSR37556 | C35: MLTD104SCOMP | D35: 1432333579 | 615899768 | E35: Toner Alternativo Para Samsung 1665 104s 104 Ml1665 Ml1865 Negro | F35: 28 | G35: 15 | H35: 26 | I35: =ROUND($H35/30,2) -> 0.87 | J35: =IF($Z35="CENSURADO",ROUND($T35/MAX($V35,3),2),ROUND($T35/$G$3,2)) -> 1 | K35: =ROUNDUP($J35*$C$3*7,0) -> 21 | L35: =MAX(0,$K35-$F35-$G35) -> 0 | M35: 6091 | N35: 1209 | O35: =$M35+$N35 -> 7300 | P35: =MIN($L35,$O35) -> 0 | Q35: Activa | R35: 1 | S35: Mediano | T35: 32 | U35: 16 | V35: 29 | W35: 1 | X35: 41 | Y35: =IF($X35=0,"",ROUND($H35/$X35,2)) -> 0.63 | Z35: =IF(AND($F35=0,$T35>=5,$W35>=3),"CENSURADO",IF(AND($Y35<>"",$Y35>=3,$T35>=10),"CENSURADO",IF($T35=0,"SIN DATO","CONFIABLE"))) -> CONFIABLE | AA35: =IF($I35=0,"",ROUND($J35/MAX($I35,0.01),2)) -> 1.15 | AB35: =IF($J35<=0,"",ROUND(($F35+$G35)/$J35,0)) -> 43 | AC35: =IF($AB35="","",$J$3+$AB35) -> 46288 | AD35: 0 | AE35: 0 | AF35: 0 | AG35: =IF($AF35=0,"",MAX(0,180-$AE35)) | AH35: 0 | AI35: =IF($AF35=0,"",$AF35*$Q$3-$AF35*$N$3) | AJ35: 4.48 | AK35: =ROUND($F35*$AJ35,0) -> 125 | AL35: =IF(AND($F35=0,$T35>0,$O35=0),"QUIEBRE Y SIN STOCK PARA ENVIAR",IF(AND($F35=0,$T35>0),"QUIEBRE",IF($F35=0,"SIN STOCK SIN DEMANDA",IF(AND($AF35>0,$AG35<>"",OR($AB35="",$AB35>$AG35)),"STOCK VIEJO EN RIESGO",IF(AND($T35=0,$H35=0),"SIN ROTACION",IF($AB35="","-",IF($AB35<14,"REPONER",IF($AB35>84,"SOBRE-STOCK","EN RANGO")))))))) -> EN RANGO
A36: IT | B36: LGAM05574 | C36: CABLEREDCAT5RJ2MY | D36: 1960865546 | 660810957 | E36: Cable De Red Utp 2 Metros Rj45 Cat 5e Patch Cord Ethernet | F36: 0 | G36: 0 | H36: 5 | I36: =ROUND($H36/30,2) -> 0.17 | J36: =IF($Z36="CENSURADO",ROUND($T36/MAX($V36,3),2),ROUND($T36/$G$3,2)) -> 2.13 | K36: =ROUNDUP($J36*$C$3*7,0) -> 45 | L36: =MAX(0,$K36-$F36-$G36) -> 45 | M36: 3089 | N36: 74 | O36: =$M36+$N36 -> 3163 | P36: =MIN($L36,$O36) -> 45 | Q36: Activa | R36: 1 | S36: Pequeño | T36: 32 | U36: 3 | V36: 15 | W36: 11 | X36: 2 | Y36: =IF($X36=0,"",ROUND($H36/$X36,2)) -> 2.5 | Z36: =IF(AND($F36=0,$T36>=5,$W36>=3),"CENSURADO",IF(AND($Y36<>"",$Y36>=3,$T36>=10),"CENSURADO",IF($T36=0,"SIN DATO","CONFIABLE"))) -> CENSURADO | AA36: =IF($I36=0,"",ROUND($J36/MAX($I36,0.01),2)) -> 12.53 | AB36: =IF($J36<=0,"",ROUND(($F36+$G36)/$J36,0)) -> 0 | AC36: =IF($AB36="","",$J$3+$AB36) -> 46245 | AD36: 0 | AE36: 163 | AF36: 6 | AG36: =IF($AF36=0,"",MAX(0,180-$AE36)) -> 17 | AH36: 2100 | AI36: =IF($AF36=0,"",$AF36*$Q$3-$AF36*$N$3) -> 24090 | AJ36: 0.47 | AK36: =ROUND($F36*$AJ36,0) -> 0 | AL36: =IF(AND($F36=0,$T36>0,$O36=0),"QUIEBRE Y SIN STOCK PARA ENVIAR",IF(AND($F36=0,$T36>0),"QUIEBRE",IF($F36=0,"SIN STOCK SIN DEMANDA",IF(AND($AF36>0,$AG36<>"",OR($AB36="",$AB36>$AG36)),"STOCK VIEJO EN RIESGO",IF(AND($T36=0,$H36=0),"SIN ROTACION",IF($AB36="","-",IF($AB36<14,"REPONER",IF($AB36>84,"SOBRE-STOCK","EN RANGO")))))))) -> QUIEBRE
A37: IT | B37: UCKV77577 | C37: EPGMR029BLACK | D37: 1130780885 | 3274793040 | E37: Auricular Gamer Con Microfono Stereo Epgmr029 Negro Negro | F37: 0 | G37: 0 | H37: 11 | I37: =ROUND($H37/30,2) -> 0.37 | J37: =IF($Z37="CENSURADO",ROUND($T37/MAX($V37,3),2),ROUND($T37/$G$3,2)) -> 1.2 | K37: =ROUNDUP($J37*$C$3*7,0) -> 26 | L37: =MAX(0,$K37-$F37-$G37) -> 26 | M37: 29 | N37: 36 | O37: =$M37+$N37 -> 65 | P37: =MIN($L37,$O37) -> 26 | Q37: Activa | R37: 1 | S37: Pequeño | T37: 30 | U37: 18 | V37: 25 | W37: 7 | X37: 1 | Y37: =IF($X37=0,"",ROUND($H37/$X37,2)) -> 11 | Z37: =IF(AND($F37=0,$T37>=5,$W37>=3),"CENSURADO",IF(AND($Y37<>"",$Y37>=3,$T37>=10),"CENSURADO",IF($T37=0,"SIN DATO","CONFIABLE"))) -> CENSURADO | AA37: =IF($I37=0,"",ROUND($J37/MAX($I37,0.01),2)) -> 3.24 | AB37: =IF($J37<=0,"",ROUND(($F37+$G37)/$J37,0)) -> 0 | AC37: =IF($AB37="","",$J$3+$AB37) -> 46245 | AD37: 0 | AE37: 0 | AF37: 0 | AG37: =IF($AF37=0,"",MAX(0,180-$AE37)) | AH37: 0 | AI37: =IF($AF37=0,"",$AF37*$Q$3-$AF37*$N$3) | AJ37: 0 | AK37: =ROUND($F37*$AJ37,0) -> 0 | AL37: =IF(AND($F37=0,$T37>0,$O37=0),"QUIEBRE Y SIN STOCK PARA ENVIAR",IF(AND($F37=0,$T37>0),"QUIEBRE",IF($F37=0,"SIN STOCK SIN DEMANDA",IF(AND($AF37>0,$AG37<>"",OR($AB37="",$AB37>$AG37)),"STOCK VIEJO EN RIESGO",IF(AND($T37=0,$H37=0),"SIN ROTACION",IF($AB37="","-",IF($AB37<14,"REPONER",IF($AB37>84,"SOBRE-STOCK","EN RANGO")))))))) -> QUIEBRE
A38: IT | B38: FZBZ18741 | C38: FOILHOLOGOLDRAINBOW-G-32X6MT | D38: 1876051914 | 3374717672 | E38: Rollo Foil Holográfico Gold Rainbow Glossy, 32cm X 6m Gold Rainbown | F38: 0 | G38: 0 | H38: 25 | I38: =ROUND($H38/30,2) -> 0.83 | J38: =IF($Z38="CENSURADO",ROUND($T38/MAX($V38,3),2),ROUND($T38/$G$3,2)) -> 1.2 | K38: =ROUNDUP($J38*$C$3*7,0) -> 26 | L38: =MAX(0,$K38-$F38-$G38) -> 26 | M38: 910 | N38: 2134 | O38: =$M38+$N38 -> 3044 | P38: =MIN($L38,$O38) -> 26 | Q38: Activa | R38: 2 | S38: Mediano | T38: 30 | U38: 16 | V38: 25 | W38: 6 | X38: 9 | Y38: =IF($X38=0,"",ROUND($H38/$X38,2)) -> 2.78 | Z38: =IF(AND($F38=0,$T38>=5,$W38>=3),"CENSURADO",IF(AND($Y38<>"",$Y38>=3,$T38>=10),"CENSURADO",IF($T38=0,"SIN DATO","CONFIABLE"))) -> CENSURADO | AA38: =IF($I38=0,"",ROUND($J38/MAX($I38,0.01),2)) -> 1.45 | AB38: =IF($J38<=0,"",ROUND(($F38+$G38)/$J38,0)) -> 0 | AC38: =IF($AB38="","",$J$3+$AB38) -> 46245 | AD38: 0 | AE38: 0 | AF38: 0 | AG38: =IF($AF38=0,"",MAX(0,180-$AE38)) | AH38: 0 | AI38: =IF($AF38=0,"",$AF38*$Q$3-$AF38*$N$3) | AJ38: 0 | AK38: =ROUND($F38*$AJ38,0) -> 0 | AL38: =IF(AND($F38=0,$T38>0,$O38=0),"QUIEBRE Y SIN STOCK PARA ENVIAR",IF(AND($F38=0,$T38>0),"QUIEBRE",IF($F38=0,"SIN STOCK SIN DEMANDA",IF(AND($AF38>0,$AG38<>"",OR($AB38="",$AB38>$AG38)),"STOCK VIEJO EN RIESGO",IF(AND($T38=0,$H38=0),"SIN ROTACION",IF($AB38="","-",IF($AB38<14,"REPONER",IF($AB38>84,"SOBRE-STOCK","EN RANGO")))))))) -> QUIEBRE
A39: IT | B39: GKBT65516 | C39: WEEDINGTOOLS-SETX6 | D39: 3105334186 | E39: Kit De 6 Herramientas Basicas Para Manualidades | F39: 12 | G39: 0 | H39: 22 | I39: =ROUND($H39/30,2) -> 0.73 | J39: =IF($Z39="CENSURADO",ROUND($T39/MAX($V39,3),2),ROUND($T39/$G$3,2)) -> 0.91 | K39: =ROUNDUP($J39*$C$3*7,0) -> 20 | L39: =MAX(0,$K39-$F39-$G39) -> 8 | M39: 18 | N39: 0 | O39: =$M39+$N39 -> 18 | P39: =MIN($L39,$O39) -> 8 | Q39: Activa | R39: 1 | S39: Mediano | T39: 29 | U39: 20 | V39: 29 | W39: 1 | X39: 25 | Y39: =IF($X39=0,"",ROUND($H39/$X39,2)) -> 0.88 | Z39: =IF(AND($F39=0,$T39>=5,$W39>=3),"CENSURADO",IF(AND($Y39<>"",$Y39>=3,$T39>=10),"CENSURADO",IF($T39=0,"SIN DATO","CONFIABLE"))) -> CONFIABLE | AA39: =IF($I39=0,"",ROUND($J39/MAX($I39,0.01),2)) -> 1.25 | AB39: =IF($J39<=0,"",ROUND(($F39+$G39)/$J39,0)) -> 13 | AC39: =IF($AB39="","",$J$3+$AB39) -> 46258 | AD39: 0 | AE39: 0 | AF39: 0 | AG39: =IF($AF39=0,"",MAX(0,180-$AE39)) | AH39: 0 | AI39: =IF($AF39=0,"",$AF39*$Q$3-$AF39*$N$3) | AJ39: 3.82 | AK39: =ROUND($F39*$AJ39,0) -> 46 | AL39: =IF(AND($F39=0,$T39>0,$O39=0),"QUIEBRE Y SIN STOCK PARA ENVIAR",IF(AND($F39=0,$T39>0),"QUIEBRE",IF($F39=0,"SIN STOCK SIN DEMANDA",IF(AND($AF39>0,$AG39<>"",OR($AB39="",$AB39>$AG39)),"STOCK VIEJO EN RIESGO",IF(AND($T39=0,$H39=0),"SIN ROTACION",IF($AB39="","-",IF($AB39<14,"REPONER",IF($AB39>84,"SOBRE-STOCK","EN RANGO")))))))) -> REPONER
A40: IT | B40: TBOR79704 | C40: CE278ACOMP | D40: 614120423 | E40: Toner Alternativo Para Ce278a 78a 278 P1606 P1606dn P1566 Negro | F40: 0 | G40: 0 | H40: 30 | I40: =ROUND($H40/30,2) -> 1 | J40: =IF($Z40="CENSURADO",ROUND($T40/MAX($V40,3),2),ROUND($T40/$G$3,2)) -> 2.55 | K40: =ROUNDUP($J40*$C$3*7,0) -> 54 | L40: =MAX(0,$K40-$F40-$G40) -> 54 | M40: 42 | N40: 0 | O40: =$M40+$N40 -> 42 | P40: =MIN($L40,$O40) -> 42 | R40: 1 | S40: Mediano | T40: 28 | U40: 7 | V40: 11 | W40: 18 | X40: 6 | Y40: =IF($X40=0,"",ROUND($H40/$X40,2)) -> 5 | Z40: =IF(AND($F40=0,$T40>=5,$W40>=3),"CENSURADO",IF(AND($Y40<>"",$Y40>=3,$T40>=10),"CENSURADO",IF($T40=0,"SIN DATO","CONFIABLE"))) -> CENSURADO | AA40: =IF($I40=0,"",ROUND($J40/MAX($I40,0.01),2)) -> 2.55 | AB40: =IF($J40<=0,"",ROUND(($F40+$G40)/$J40,0)) -> 0 | AC40: =IF($AB40="","",$J$3+$AB40) -> 46245 | AD40: 0 | AE40: 0 | AF40: 0 | AG40: =IF($AF40=0,"",MAX(0,180-$AE40)) | AH40: 0 | AI40: =IF($AF40=0,"",$AF40*$Q$3-$AF40*$N$3) | AJ40: 2.69 | AK40: =ROUND($F40*$AJ40,0) -> 0 | AL40: =IF(AND($F40=0,$T40>0,$O40=0),"QUIEBRE Y SIN STOCK PARA ENVIAR",IF(AND($F40=0,$T40>0),"QUIEBRE",IF($F40=0,"SIN STOCK SIN DEMANDA",IF(AND($AF40>0,$AG40<>"",OR($AB40="",$AB40>$AG40)),"STOCK VIEJO EN RIESGO",IF(AND($T40=0,$H40=0),"SIN ROTACION",IF($AB40="","-",IF($AB40<14,"REPONER",IF($AB40>84,"SOBRE-STOCK","EN RANGO")))))))) -> QUIEBRE
A41: IT | B41: HSXJ89262 | C41: K227BKMEDIAUSB | D41: 1377072473 | E41: Teclado Global K227 Multimedia Con Cable Usb Negro Negro Español De Latinoaméric | F41: 0 | G41: 20 | H41: 2 | I41: =ROUND($H41/30,2) -> 0.07 | J41: =IF($Z41="CENSURADO",ROUND($T41/MAX($V41,3),2),ROUND($T41/$G$3,2)) -> 1.17 | K41: =ROUNDUP($J41*$C$3*7,0) -> 25 | L41: =MAX(0,$K41-$F41-$G41) -> 5 | M41: 13623 | N41: 63 | O41: =$M41+$N41 -> 13686 | P41: =MIN($L41,$O41) -> 5 | Q41: Activa | R41: 2 | S41: Mediano | T41: 28 | U41: 6 | V41: 24 | W41: 7 | X41: 0 | Y41: =IF($X41=0,"",ROUND($H41/$X41,2)) | Z41: =IF(AND($F41=0,$T41>=5,$W41>=3),"CENSURADO",IF(AND($Y41<>"",$Y41>=3,$T41>=10),"CENSURADO",IF($T41=0,"SIN DATO","CONFIABLE"))) -> CENSURADO | AA41: =IF($I41=0,"",ROUND($J41/MAX($I41,0.01),2)) -> 16.71 | AB41: =IF($J41<=0,"",ROUND(($F41+$G41)/$J41,0)) -> 17 | AC41: =IF($AB41="","",$J$3+$AB41) -> 46262 | AD41: 0 | AE41: 166 | AF41: 7 | AG41: =IF($AF41=0,"",MAX(0,180-$AE41)) -> 14 | AH41: 3290 | AI41: =IF($AF41=0,"",$AF41*$Q$3-$AF41*$N$3) -> 28105 | AJ41: 2.34 | AK41: =ROUND($F41*$AJ41,0) -> 0 | AL41: =IF(AND($F41=0,$T41>0,$O41=0),"QUIEBRE Y SIN STOCK PARA ENVIAR",IF(AND($F41=0,$T41>0),"QUIEBRE",IF($F41=0,"SIN STOCK SIN DEMANDA",IF(AND($AF41>0,$AG41<>"",OR($AB41="",$AB41>$AG41)),"STOCK VIEJO EN RIESGO",IF(AND($T41=0,$H41=0),"SIN ROTACION",IF($AB41="","-",IF($AB41<14,"REPONER",IF($AB41>84,"SOBRE-STOCK","EN RANGO")))))))) -> QUIEBRE
...

Sheet COLUMNAS
A1: QUÉ ES CADA COLUMNA
A2: Las columnas en celeste se calculan solas. Las grises vienen de un reporte.
A4: BLOQUE | B4: COLUMNA | C4: DE DÓNDE SALE | D4: QUÉ SIGNIFICA
A5: PARA ARMAR EL ENVÍO | B5: Cuenta | C5: Fijo | D5: IT o MT. Hoy solo hay IT cargada.
B6: Código ML | C6: Reporte general de stock de Full | D6: El código interno de ML del producto.
B7: SKU | C7: Reporte general de stock de Full | D7: Nuestro código.
B8: MLA (publicación) | C8: Reporte general de stock de Full | D8: El número de publicación. Si un SKU tiene varias, aparecen todas.
B9: Título | C9: Reporte general de stock de Full | D9: Nombre del producto en ML.
B10: Stock en Full | C10: Reporte general de stock de Full | D10: Unidades aptas para vender que están hoy en el depósito de ML.
B11: Envíos pendientes | C11: Reporte general de stock de Full | D11: Unidades que ya salieron y ML todavía no recibió.
B12: Ventas 30 días | C12: Reporte general de stock de Full | D12: El número que informa ML. OJO: es el que puede estar censurado.
B13: Ventas diarias simple | C13: CALCULADA | D13: Ventas 30 días dividido 30. Es lo que muestra cualquier reporte. Puede estar mal.
B14: Ventas diarias corregida | C14: CALCULADA | D14: Si el dato está censurado, se divide por los días que tuvo stock en lugar de por 30. Esta es la que se usa para todo lo demás.
B15: Stock objetivo | C15: CALCULADA | D15: Ventas diarias corregida por las semanas objetivo por 7. Las semanas se cambian en la celda C3.
B16: Falta enviar | C16: CALCULADA | D16: Stock objetivo menos lo que hay en Full menos lo que va en camino. Nunca da negativo.
B17: Stock Táctica | C17: Sistema Táctica | D17: Unidades disponibles en Táctica.
... B20: ENVIAR POSIBLE | C20: CALCULADA | D20: El menor entre lo que falta enviar y lo que hay disponible. Si es menor que "Falta enviar", el límite no es Full: no tenemos la mercadería.
A21: CONTROL DE LA PUBLICACIÓN | B21: Estado publicación | C21: Reporte general de stock de Full | D21: Activa, pausada, etc. Una pausada vende cero aunque tenga stock.
B22: Publ. | C22: CALCULADA | D22: Cuántas publicaciones tiene ese SKU. Si es más de 1, el stock se comparte.
B23: Tamaño | C23: Reporte general de stock de Full | D23: Chico, mediano, grande. Define la tarifa de almacenamiento.
A24: CÓMO SE MIDIÓ LA DEMANDA | B24: Unidades 32d | C24: Reporte de ventas con fecha | D24: Unidades realmente vendidas en el período, descontando canceladas y devueltas.
B25: Días con venta | C25: Reporte de ventas con fecha | D25: En cuántos días distintos hubo al menos una venta.
B26: Ventana con stock | C26: Reporte de ventas con fecha | D26: Días entre la primera y la última venta. Aproxima cuántos días tuvo stock. ESTE ES EL DATO CLAVE.
B27: Días sin vender | C27: Reporte de ventas con fecha | D27: Cuántos días pasaron desde la última venta hasta hoy. Si son muchos y el stock es cero, se agotó.
B28: Stock prom 30d ML | C28: Reporte general de stock de Full | D28: Stock promedio que tuvo durante el mes, según ML.
B29: Rotación | C29: CALCULADA | D29: Ventas 30 días dividido stock promedio. Arriba de 3 significa que estuvo agotado buena parte del mes.
B30: Estado del dato | C30: CALCULADA | D30: CENSURADO: se agotó, así que la venta es un piso y no una medición. CONFIABLE: tuvo stock. SIN DATO: no vendió.
B31: Factor | C31: CALCULADA | D31: Cuántas veces subestima el reporte mensual. Factor 6 significa que el reporte muestra la sexta parte de la demanda real.
A32: CUÁNDO SE QUIEBRA | B32: Cobertura (días) | C32: CALCULADA | D32: Stock en Full más en camino, dividido las ventas diarias corregidas.
B33: Quiebre estimado | C33: CALCULADA | D33: La fecha en que llega a cero si la venta sigue al mismo ritmo.
A34: ANTIGÜEDAD Y CARGOS | B34: No aptas | C34: Reporte general de stock de Full | D34: Unidades que ML no puede vender. Ocupan lugar igual.
B35: Antigüedad máx | C35: Reporte de cargos por antigüedad | D35: Días de la unidad más vieja de ese SKU.
B36: Unid. 4-6 meses | C36: Reporte de cargos por antigüedad | D36: Unidades entre 120 y 179 días. Hoy pagan la tarifa de la celda N3.
B37: Días al límite 180 | C37: CALCULADA | D37: Cuántos días faltan para que esas unidades pasen al tramo caro.
B38: Cargo actual | C38: Reporte de cargos por antigüedad | D38: Lo que se está pagando por stock antiguo de ese SKU.
B39: Aumento si cruza | C39: CALCULADA | D39: Cuánto más se pagaría si esas unidades cruzan los 180 días. La tarifa salta de $470 a $4.485: nueve veces.
A40: VALOR | B40: Costo USD | C40: Sistema ECOM | D40: Costo unitario. 19 SKUs no lo tienen cargado.
B41: Valor en Full USD | C41: CALCULADA | D41: Stock en Full por el costo. Es un piso, porque falta el costo de algunos SKUs.
A42: ESTADO | B42: ALERTA | C42: CALCULADA | D42: El estado del SKU. Describe la situación, no indica qué hacer.
A44: LOS ESTADOS DE LA COLUMNA ALERTA
...
